Workbook

Sheet Read Me
A1: New Postpaid Activation
A2: Open questions for VFQ business stakeholders
A4: Generated by | C4: reference/scripts/build_postpaid_open_questions.py
A5: Source of record | C5: VFQ_DXP_Postpaid_Activation_Open_Questions_Reference.md
A6: Journey scope | C6: src/modules/mobile-postpaid/screens/NewPostpaidWizard.tsx (11 steps)
A7: Checked against | C7: reference/.knowledge/ (83 indexed source documents)
A8: Related artefacts | C8: reference/blueprint/conflict-report.md (corpus conflicts, broader scope); reference/.knowledge/INDEX.md (source confidence)
A10: This workbook is generated. Do not hand-edit.
A11: Edit the markdown and re-run the script. Opening this file in Excel and saving it will silently rewrite it, and the next regeneration will discard the change. Every question, status, citation and ranking below is parsed out of the markdown - nothing is typed into the script.
A15: Counts
A16: Measure | B16: Count | C16: Meaning
A17: Open questions total | B17: =COUNTA('Open Questions'!$A$2:$A$58) -> 57 | C17: One row per question on the Open Questions sheet.
A18: OWED - already committed | B18: =COUNTIF('Open Questions'!$C$2:$C$58,"OWED") -> 9 | C18: Logged as a BRSD v2.0 dependency. Chase the owner rather than re-asking.
A19: GAP - not yet logged | B19: =COUNTIF('Open Questions'!$C$2:$C$58,"GAP") -> 48 | C19: Found while building. The app carries an assumption today.
A20: Areas covered | B20: =SUMPRODUCT((COUNTIF('Open Questions'!$B$2:$B$58,'Open Questions'!$B$2:$B$58)>0)/COUNTIF('Open Questions'!$B$2:$B$58,'Open Questions'!$B$2:$B$58)) -> 11 | C20: Distinct values in the Area column, counted without a helper range.
A21: Questions in a priority area | B21: =COUNT('Open Questions'!$H$2:$H$58) -> 33 | C21: Not individually ranked - these sit in one of the 8 areas on the Priority Shortlist sheet.
A23: By area
A24: Area | B24: Questions | C24: Of which OWED
A25: Identification and KYC | B25: =COUNTIF('Open Questions'!$B$2:$B$58,$A25) -> 8 | C25: =COUNTIFS('Open Questions'!$B$2:$B$58,$A25,'Open Questions'!$C$2:$C$58,"OWED") -> 0
A26: Eligibility and line caps | B26: =COUNTIF('Open Questions'!$B$2:$B$58,$A26) -> 8 | C26: =COUNTIFS('Open Questions'!$B$2:$B$58,$A26,'Open Questions'!$C$2:$C$58,"OWED") -> 0
A27: Credit control, HRN and deposits | B27: =COUNTIF('Open Questions'!$B$2:$B$58,$A27) -> 7 | C27: =COUNTIFS('Open Questions'!$B$2:$B$58,$A27,'Open Questions'!$C$2:$C$58,"OWED") -> 2
A28: CBM approval workflow | B28: =COUNTIF('Open Questions'!$B$2:$B$58,$A28) -> 6 | C28: =COUNTIFS('Open Questions'!$B$2:$B$58,$A28,'Open Questions'!$C$2:$C$58,"OWED") -> 1
A29: Number selection | B29: =COUNTIF('Open Questions'!$B$2:$B$58,$A29) -> 5 | C29: =COUNTIFS('Open Questions'!$B$2:$B$58,$A29,'Open Questions'!$C$2:$C$58,"OWED") -> 1
A30: Device on Installment (DOI) | B30: =COUNTIF('Open Questions'!$B$2:$B$58,$A30) -> 4 | C30: =COUNTIFS('Open Questions'!$B$2:$B$58,$A30,'Open Questions'!$C$2:$C$58,"OWED") -> 0
A31: SIM, eSIM and provisioning | B31: =COUNTIF('Open Questions'!$B$2:$B$58,$A31) -> 3 | C31: =COUNTIFS('Open Questions'!$B$2:$B$58,$A31,'Open Questions'!$C$2:$C$58,"OWED") -> 0
A32: Address capture | B32: =COUNTIF('Open Questions'!$B$2:$B$58,$A32) -> 3 | C32: =COUNTIFS('Open Questions'!$B$2:$B$58,$A32,'Open Questions'!$C$2:$C$58,"OWED") -> 0
A33: Forms, payment and notifications | B33: =COUNTIF('Open Questions'!$B$2:$B$58,$A33) -> 7 | C33: =COUNTIFS('Open Questions'!$B$2:$B$58,$A33,'Open Questions'!$C$2:$C$58,"OWED") -> 3
A34: Field-level specification | B34: =COUNTIF('Open Questions'!$B$2:$B$58,$A34) -> 5 | C34: =COUNTIFS('Open Questions'!$B$2:$B$58,$A34,'Open Questions'!$C$2:$C$58,"OWED") -> 1
A35: Billing profile data references | B35: =COUNTIF('Open Questions'!$B$2:$B$58,$A35) -> 1 | C35: =COUNTIFS('Open Questions'!$B$2:$B$58,$A35,'Open Questions'!$C$2:$C$58,"OWED") -> 1

Sheet Open Questions
A1: ID | B1: Area | C1: Status | D1: Committed as | E1: Question | F1: What is known / why it matters | G1: Required Data | H1: Priority area
A2: Q01 | B2: Identification and KYC | C2: GAP | E2: What is the "one unspecified exception" to the QID-mandatory rule? | F2: The foundational rule is confirmed: postpaid cannot be sold against any ID type other than QID, "with one unspecified exception to be discussed later". That discussion is not in the corpus. This is the single highest-value open question in the journey, because it defines who can be sold to at all. | G2: business-workshop-session-1-postpaid-service-20260625-124533-4b09c0db [00:25:18] | H2: 1
A3: Q02 | B3: Identification and KYC | C3: GAP | E3: Is Diplomatic ID inside or outside that rule? | F3: The app currently sells directly against QID or Diplomatic ID, and routes Passport / GCC ID / other exception documents to CBM approval. The QID-mandatory rule as written would exclude Diplomatic ID too. Needs an explicit yes/no. | H3: 1
A4: Q03 | B4: Identification and KYC | C4: GAP | E4: What is the ID expiry policy? | F4: No source document states one, and the source dataset carried no expiry field at all. Open: is an expired document a hard stop or a correctable warning? Is there a minimum remaining validity (e.g. must not expire within the contract term)? What about a document with no expiry recorded? | H4: 1
A5: Q04 | B5: Identification and KYC | C5: GAP | E5: How many scan attempts before the agent may key the number manually? | F5: The app allows four, taken from a reference screenshot showing "Scan Attempts: 0 / 4". No business rule states it. Also open: after four failures, is manual entry actually permitted, or must the customer be turned away? | H5: 1
A6: Q05 | B6: Identification and KYC | C6: GAP | E6: What does MOI return, and what is authoritative? | F6: The workshop mentions "up to 5-6 name fields". The app splits a single name on whitespace into First / Last, which is a guess. Open: the real field list, and which MOI-sourced fields the agent may override. | H6: 1
A7: Q06 | B7: Identification and KYC | C7: GAP | E7: Is the MOI national address service available? | F7: Logged as an action item ("Vishal to enable") with no recorded outcome. | G7: business-workshop-session-1-postpaid-service-20260625-124533-4b09c0db [00:32:41] | H7: 1
A8: Q07 | B8: Identification and KYC | C8: GAP | E8: Does IDWise OCR support Arabic? | F8: Raised as an open question in workshop and never answered. Also open: behaviour on a damaged or worn card, and timeout handling. | G8: business-workshop-day2-session-2-postpaid-service-20260628-1-bf394204 [00:51:24] | H8: 1
A9: Q08 | B9: Identification and KYC | C9: GAP | E9: Security questions / customer verification model. | F9: The workshop session that covered this is materially incomplete - only ~29 of 186 minutes decoded. Whatever was agreed about the security-question model and KYC verification procedure exists only in the facilitators' own notes or the raw recording. | G9: business-workshop-day5-session-1-postpaid-service-20260701-0-a55f2808 (medium confidence) | H9: 1
A10: Q09 | B10: Eligibility and line caps | C10: GAP | E10: What exactly does each eligibility check query? | F10: The journey runs seven checks (ID validity, age, ID type, collections, security, deals, active lines). The corpus names them but never says which system answers each one (BRM? Collections? a blacklist DB?), whether they run in sequence or parallel, what the timeout is, or what the agent should do when a check system is unavailable. | G10: order-validation-business-rules-45d0e9f0
A11: Q10 | B11: Eligibility and line caps | C11: GAP | E11: Is the minimum age 18? | F11: The app assumes it. No source states an age.
A12: Q11 | B12: Eligibility and line caps | C12: GAP | E12: Is the 5-line cap for non-nationals per operator or across all Qatari operators? | F12: "Per operator" is stated but not defined. If it is market-wide, the check cannot be answered from VFQ data alone. | G12: business-workshop-session-1-postpaid-service-20260625-124533-4b09c0db [00:53:54-00:58:37]
A13: Q12 | B13: Eligibility and line caps | C13: GAP | E13: At which step is the line-cap check performed - Contact, Plan or Submit, and what exact wording does the agent see?
A14: Q13 | B14: Eligibility and line caps | C14: GAP | E14: What is the "authorized officer" override? | F14: The cap is overridable by an authorized-officer flag on the account. Open: who holds that role, how the flag is set, and whether it is an in-journey action or a prerequisite.
A15: Q14 | B15: Eligibility and line caps | C15: GAP | E15: Does the blacklist category change the outcome? | F15: The app distinguishes a collections listing (soft stop, prepaid still offerable) from a security listing (hard stop, nothing offerable). That distinction is an inference. Open: the real category list and the disposition for each.
A16: Q15 | B16: Eligibility and line caps | C16: GAP | E16: Which commitment-penalty states block a new connection? | F16: The source data has no field for this. Open: does a *pending* penalty block, or only an applied one? Does it block all new connections or only same-product ones?
A17: Q16 | B17: Eligibility and line caps | C17: GAP | E17: Do barring states affect new-connection eligibility? | F17: Barring status/type/reason are placeholders throughout - BRSD v3.1 Section 2.13 leaves their Data Ref (DR-01..07) undefined in Annex_01. Open: the valid states, and whether an existing barred line blocks a new sale.
A18: Q17 | B18: Credit control, HRN and deposits | C18: OWED | D18: D-08 | E18: The full HRN advance payment matrix. | F18: Known: Nepalese / HRN customers pay QR 100 in advance, driven by nationality and sales channel and explicitly not by plan value, adjusted against the first bill. | G18: The complete nationality list the amount per nationality Channel-specific variations Whether activation is blocked if it is not paid. | H18: 3
A19: Q18 | B19: Credit control, HRN and deposits | C19: OWED | D19: D-07 | E19: Collections outstanding-dues thresholds. | F19: Known: a billing profile enters collections once overdue exceeds 100. Missing: whether 100 QAR is fixed or configurable, whether it applies uniformly across segments, and the precise definition of "overdue" versus "outstanding". | H19: 3
A20: Q19 | B20: Credit control, HRN and deposits | C20: GAP | E20: Is the collections threshold the same for mobile as for fibre? | F20: The Fibre BRSD's own open-items log (OI-04) records an unresolved dispute on exactly this - one side says the threshold should differ by product, the other says it should be uniform. No value is agreed anywhere. | G20: vfq-fibre-brsd-v1-2-068eebe3 [OI-04] | H20: 3
A21: Q20 | B21: Credit control, HRN and deposits | C21: GAP | E21: What is the default credit limit for a Qatari national? | F21: Known: 1,000 QAR for an expat on a new account, 50 QAR for HRN. The Qatari default is never stated, and it is unclear whether other nationality segments exist. | G21: business-workshop-day5-session-2-postpaid-service-20260701-1-d62f0cd4 [00:59:40] | H21: 3
A22: Q21 | B22: Credit control, HRN and deposits | C22: GAP | E22: What are the credit-limit boundaries an agent may select within? | F22: The workshop records that there is "no system restriction today preventing any agent from selecting any credit limit value", flagged as an "uncontrolled credit exposure" risk. Modernization has to define the control. Open: the permitted range per segment, and whether an out-of-range value routes to approval or is simply refused. | G22: business-workshop-day5-session-2-postpaid-service-20260701-1-d62f0cd4 [01:00:21] | H22: 3
A23: Q22 | B23: Credit control, HRN and deposits | C23: GAP | E23: Is a deposit required, and how does it interact with the credit limit? | F23: BR-270 requires "a minimum deposit of QR 2,000 or a valid credit card on file" to establish a postpaid credit limit; the Consumer Postpaid CAF also mentions QR 2,000. Open: when this applies, whether it is collected in this journey, and how it relates to the HRN advance. Note the old deposit-for-increase process was discontinued because there was no refund mechanism when customers disconnected - so a refund policy is needed before reintroducing it. | H23: 3
A24: Q23 | B24: Credit control, HRN and deposits | C24: GAP | E24: What is the bill limit ("spend limit") Agent Minimum, currently? | F24: The corpus gives three data points for the same product: Bill Limit Mobile Plus at 75 in two journeys and 80 in a third, described as "Agent Min raised to 80". Bill Limit Mobile is 50 throughout. This looks like per-promotion configuration that changed over time rather than a contradiction - but the authoritative current mapping of promotion to Agent Minimum is not in the corpus. Enforced at Validate with Siebel error SBL-EXL-00151. | G24: guided-journeys-postpaid-open-ui-desktop-new-postpaid-f8227f90, guided-journeys-mnp-postpaid-open-ui-desktop-mnp-postpaid-6cb03f33, guided-journeys-pre-to-post-desktop-vanilla-pre-to-post-6d6b61ce | H24: 3
A25: Q24 | B25: CBM approval workflow | C25: GAP | E25: What conditions route an order to CBM approval rather than auto-completing? | F25: The app routes on B2B2C and on the HRN/credit-limit variant (BR-268, UJ-081). Open: whether high credit limits, pre-existing connections, exception ID types, or device installments also trigger it. | H25: 2
A26: Q25 | B26: CBM approval workflow | C26: GAP | E26: What does the CBM approver actually validate, and against which systems? | H26: 2
A27: Q26 | B27: CBM approval workflow | C27: GAP | E27: Can CBM modify order details before approving, or only approve and reject? | H27: 2
A28: Q27 | B28: CBM approval workflow | C28: GAP | E28: What is the SLA for an approval decision, and what does the agent or customer see while waiting? | H28: 2
A29: Q28 | B29: CBM approval workflow | C29: GAP | E29: What is the difference between "Reject - Correction" and "Reject - Drop Order"? | F29: Both appear in the UI. Whether the first returns an editable order to the originating agent is assumed, not documented. | H29: 2
A30: Q29 | B30: CBM approval workflow | C30: OWED | D30: MPAR_001_JSM_02 | E30: The agent role privilege matrix | F30: is listed as TBD in the BRSD and never populated. This determines who can approve, who can override a cap, and who can set a credit limit. | H30: 2
A31: Q30 | B31: Number selection | C31: OWED | D31: D-02 | E31: The plan-price to star-number-price eligibility matrix. | F31: Known only as an approximation: "a 200 Riyal plan entitles ~5,000 Riyal worth of star number", with the customer paying the delta at point of sale. Missing: the exact formula or lookup table, the exceptions by product, and how the delta is calculated and charged. | G31: business-workshop-session-1-postpaid-service-20260625-124533-4b09c0db [01:20:26] | H31: 6
A32: Q31 | B32: Number selection | C32: GAP | E32: What determines which numbers an agent sees? | F32: BR-756 says numbers are auto-selected for fixed and prepaid (zero-rated) but not for mobile postpaid "since those numbers carry a price" - yet nothing in the number inventory distinguishes zero-rated from priced. Open: the filter and visibility logic for the postpaid picker. | H32: 6
A33: Q32 | B33: Number selection | C33: GAP | E33: How long is a reserved number held before auto-release? | H33: 6
A34: Q33 | B34: Number selection | C34: GAP | E34: What is the star-number tier and pricing structure? | F34: The app seeds Gold / Silver / Platinum tiers priced by pattern strength. That model is invented; only a single Gold number at 500 QAR was evidenced. | H34: 6
A35: Q34 | B35: Number selection | C35: GAP | E35: Who reserves a number, and on what authority? | F35: The Number Management Portal is in scope per Day 5 Session 2, but the agent-facing workflow is not described. | H35: 6
A36: Q35 | B36: Device on Installment (DOI) | C36: GAP | E36: Can DOI be sold inside a new postpaid activation, or only afterwards? | F36: Day 1 explicitly deferred DOI; Day 5 discussed it as a separate journey. The app includes it as step 6 of the activation. This needs confirming either way. | H36: 7
A37: Q36 | B37: Device on Installment (DOI) | C37: GAP | E37: Is DOI order submission manual or automated? | F37: Recorded as an unresolved disagreement between workshop participants, with a confirm action assigned to Hisham and no recorded outcome. | G37: business-workshop-day5-session-2-postpaid-service-20260701-1-d62f0cd4 [01:14:40] | H37: 7
A38: Q37 | B38: Device on Installment (DOI) | C38: GAP | E38: What is the device affordability rule? | F38: The app gates device price at five times the credit limit. That multiplier is invented. Open: the real affordability test, if any. | H38: 7
A39: Q38 | B39: Device on Installment (DOI) | C39: GAP | E39: What installment terms are offered? | F39: The app offers 6, 12 and 24 months. No source states the available terms, the interest or fee treatment, or eligibility by tenure. | H39: 7
A40: Q39 | B40: SIM, eSIM and provisioning | C40: GAP | E40: What is the real eSIM provisioning flow? | F40: The app produces a GSMA SGP.22-shaped activation string against a mock SM-DP+; there is no integration contract in the corpus. Open: the provisioning call, the QR delivery mechanism, and the failure and retry path.
...

Sheet Priority Shortlist
A1: Rank | B1: Ask this first | C1: Why it leads
A2: 1 | B2: The QID-mandatory exception, and whether Diplomatic ID is in or out (S1). | C2: Defines addressable customers.
A3: 2 | B3: CBM approval - triggers, scope, SLA, reject semantics (S4). | C3: An entire downstream workflow with no specification.
A4: 3 | B4: Credit limit boundaries and the agent-selection control (S3). | C4: Carries a named financial risk.
A5: 4 | B5: HRN advance matrix D-08 and collections thresholds D-07 (S3). | C5: Already owed; both gate eligibility.
A6: 5 | B6: Role privilege matrix MPAR_001_JSM_02 (S4). | C6: Blocks approval, override and credit-setting design.
A7: 6 | B7: Star-number entitlement formula D-02 (S5). | C7: Blocks pricing at point of sale.
A8: 7 | B8: DOI - in-journey or separate, manual or automated (S6). | C8: Decides whether step 6 belongs in this wizard at all.
A9: 8 | B9: ZSB mandatory for mobile - manual versus workshop (S8). | C9: A documented contradiction with a blocking-versus-advisory outcome.
A11: Ranked by how much of the journey is blocked behind the answer, not by how hard the question is to ask. The (Sn) marker is the Open Questions area it belongs to.

Sheet Artefacts to Request
A1: # | B1: Request this document or outcome, not an answer
A2: 1 | B2: The raw recording or facilitator notes for Business Workshop Day 5 Session 1 (only ~29 of 186 minutes decoded). Customer verification, QID scanning rules and the security-question model were on that agenda.
A3: 2 | B3: The outcome of the DOI automation action assigned to Hisham.
A4: 3 | B4: The outcome of the MOI national address service action assigned to Vishal.
A5: 4 | B5: The completed Annex_01 for BRSD v3.1 Section 2.13 (DR-01..07).
A7: These are not questions a stakeholder can answer in a meeting - they are existing artefacts or recorded action outcomes that someone already holds.
