Workbook

Sheet Agent 360
A1: Agent 360 – Channel Access Matrix
A2: One row per Agent 360 tile option. Repeated options are consolidated and visible sub-details are listed separately. All channel permissions default to Read & Write.
A4: Sequence | B4: View / Tile | C4: Component | D4: Sub Details | E4: Actions / Interaction | F4: Image Reference | G4: Telesales | H4: Call Center - Onshore | I4: Call Center - Offshore | J4: CMT - Mobile | K4: CMT - Fixed & Backoffice | L4: Business Care | M4: Collections & Billing | N4: Retail/Franchise (@GIRI) | O4: Direct Sales/Mass Market (@GIRI) | P4: EBU Sales (@TINA) | Q4: EBU Operations (@TINA) | R4: Business Justification | S4: Final Approval
A5: 1 | B5: Icons on Header | C5: Duplicate Screen | E5: Open Duplicate Screen | F5: Agent 360 Screen 1 | G5: NA | H5: NA | I5: NA | J5: NA | K5: NA | L5: NA | M5: NA | P5: NA | Q5: NA
A6: 2 | B6: Icons on Header | C6: Global Screen | D6: Bulk Activation SMS Template (Manual & Automatic) TT Hashtags TT Actual Issue | E6: Open Global Screen | F6: Agent 360 Screen 1 | G6: Read & Write | H6: Read & Write | I6: NA | J6: Read & Write | K6: Read & Write | L6: Read & Write | M6: Read & Write | N6: Read & Write | O6: N/A | P6: Read Only | Q6: Read & Write
A7: 3 | B7: Icons on Header | C7: Communications (CTI) | E7: Open Communications (CTI) | F7: Agent 360 Screen 1 | G7: Read & Write | H7: Read & Write | I7: NA | J7: Read & Write | K7: View Only | L7: Read & Write | M7: Read & Write | N7: N/A | O7: N/A
A8: 4 | B8: Icons on Header | C8: Notes | E8: Open Notes | F8: Agent 360 Screen 1 | G8: Read & Write | H8: Read & Write | I8: Read & Write | J8: Read & Write | K8: Read & Write | L8: Read & Write | M8: Read & Write | N8: Read & Write | O8: Read & Write
A9: 5 | B9: Icons on Header | C9: Notifications | E9: Open Notifications | F9: Agent 360 Screen 1 | G9: Read Only | H9: Read Only | I9: Read & Write | J9: Read & Write | K9: Read & Write | L9: Read & Write | M9: Read & Write | N9: Read & Write | O9: Read & Write
A10: 6 | B10: Icons on Header | C10: Settings | E10: Open Settings | F10: Agent 360 Screen 1 | G10: Read & Write | H10: Read & Write | I10: Read & Write | J10: Read & Write | K10: Read & Write | L10: Read & Write | M10: Read & Write | N10: Read & Write | O10: Read & Write
A11: 7 | B11: Side Icons | C11: Search | D11: Search by Phone Search by Contact ID | E11: Open Search | F11: Agent 360 Screen 1 | G11: Read & Write | H11: Read & Write | I11: Read & Write | J11: Read & Write | K11: Read & Write | L11: Read & Write | M11: Read & Write | N11: Read & Write | O11: N/A
A12: 8 | B12: Side Icons | C12: ProRata Calculator | E12: Open ProRata Calculator | F12: Agent 360 Screen 1 | G12: Read & Write | H12: Read & Write | I12: Read & Write | J12: Read & Write | K12: Read & Write | L12: Read & Write | M12: Read & Write | N12: Read & Write | O12: Read & Write
A13: 9 | B13: Tabs | C13: Home | E13: Open Home | F13: Agent 360 Screen 1 | G13: Read & Write | H13: Read & Write | I13: Read & Write | J13: Read & Write | K13: Read & Write | L13: Read & Write | M13: Read & Write | N13: Read & Write | O13: Read & Write
A14: 10 | B14: Tabs | C14: Assets | E14: Open Assets | F14: Agent 360 Screen 1 | G14: Read & Write | H14: Read & Write | I14: Read & Write | J14: Read & Write | K14: Read & Write | L14: Read & Write | M14: Read & Write | N14: Read & Write | O14: N/A
A15: 11 | B15: Tabs | C15: Trouble Tickets Dashboard | E15: Open Trouble Tickets Dashboard | F15: Agent 360 Screen 1 | G15: Read & Write | H15: Read & Write | I15: NA | J15: Read & Write | K15: Read & Write | L15: Read & Write | M15: Read & Write | N15: Read & Write | O15: View Only
A16: 12 | B16: Tabs | C16: Contacts | E16: Open Contacts | F16: Agent 360 Screen 1 | G16: Read & Write | H16: Read & Write | I16: Read & Write | J16: Read & Write | K16: Read & Write | L16: Read & Write | M16: Read & Write | N16: Read & Write | O16: N/A
A17: 13 | B17: Tabs | C17: Accounts | E17: Open Accounts | F17: Agent 360 Screen 1 | G17: Read & Write | H17: Read & Write | I17: Read & Write | J17: Read & Write | K17: Read & Write | L17: Read & Write | M17: Read & Write | N17: Read & Write | O17: N/A
A18: 14 | B18: Tabs | C18: Prospect | E18: Open Prospect | F18: Agent 360 Screen 1 | G18: Read & Write | H18: Read & Write | I18: NA | J18: Read & Write | K18: NA | L18: Read & Write | M18: Read & Write | N18: Read & Write | O18: N/A
A19: 15 | B19: Tabs | C19: Sales Order | E19: Open Sales Order | F19: Agent 360 Screen 1 | G19: Read & Write | H19: Read & Write | I19: Read & Write | J19: Read & Write | K19: Read & Write | L19: Read & Write | M19: Read & Write | N19: Read & Write | O19: Read & Write
A20: 16 | B20: Tabs | C20: MNP | E20: Open MNP | F20: Agent 360 Screen 1 | G20: Read & Write | H20: Read & Write | I20: NA | J20: Read & Write | K20: NA | L20: Read & Write | M20: Read & Write | N20: Read & Write | O20: Read & Write
A21: 17 | B21: Tabs | C21: Blacklist Customers | E21: Open Blacklist Customers | F21: Agent 360 Screen 1 | G21: Read & Write | H21: Read & Write | I21: NA | J21: Read & Write | K21: Read & Write | L21: Read & Write | M21: Read & Write | N21: Read & Write | O21: View Only
A22: 18 | B22: Tabs | C22: Queue | E22: Open Queue | F22: Agent 360 Screen 1 | G22: Read & Write | H22: Read & Write | I22: Read & Write | J22: Read & Write | K22: Read & Write | L22: Read & Write | M22: Read & Write | N22: Read & Write | O22: View Only
A23: 19 | B23: Tabs | C23: Trouble Tickets | E23: Open Trouble Tickets | F23: Agent 360 Screen 1 | G23: Read & Write | H23: Read & Write | I23: Read & Write | J23: Read & Write | K23: Read & Write | L23: Read & Write | M23: Read & Write | N23: Read & Write | O23: View Only
... A41: 37 | B41: Tabs | C41: Order Tasks | E41: Open Order Tasks | F41: Agent 360 Screen 1 | G41: Read & Write | H41: Read & Write | I41: NA | J41: Read & Write | K41: Read & Write | L41: Read & Write | M41: Read & Write | N41: Read & Write | O41: N/A
A42: 38 | B42: Tabs | C42: My Adjustments | G42: Read & Write | H42: Read & Write | K42: Read & Write | N42: Read & Write | O42: N/A | R42: it will support the agent to follow up on the adjustments he raised and upadte the customers on teh status
A43: 39 | B43: Tabs | C43: Returned/Rejected Ticket | G43: Read & Write | H43: Read & Write | K43: Read & Write | N43: Read & Write | O43: Read & Write | R43: It will help the agent to follow up on the returned and rejected tickets, update it if needed, it will hep to reduce the effort on customer and expedit the resolution
A44: 40 | B44: Tabs | C44: ITSM Ticket | K44: Read & Write | N44: Read & Write | O44: N/A | R44: It helps agents track ITSM tickets raised with technology ( after OWS integration with Siebel)
B45: Tabs | C45: WFM Ticket | K45: Read & Write | N45: Read & Write | O45: N/A | R45: It helps agents track WFM tickets raised with Field ( after OWS integration with Siebel)
C46: Bill Simulation view | N46: Read & Write
C47: Qnomy Token management 1.Token calling 2.Qnomy summary (number of customers served & handlig time) 3. Current shift avg handling time 4.Current shift no of waiting customers to be served | N47: Read & Write
C48: Medallia/TNPS view 1.Current shift total responses 2.Current shift total response rate 3.Current shift summary(Promoters/Passive/Detractors) | N48: View Only
C49: RFS search view 1. Search options as in RFS portal 2. Recommendation and link to start 5G or Fiber activation journeys | N49: Read & Write
C50: NAS 1.
C51: Agent History view for orders (expandable for more than 5 entries) Includes last 5 orders with 1. order No. 2. order type (SIM swap, Prepaid, Postpaid, Fiber, 5G) 3. order status
C52: Agent history view for TT (Closed, Pending and return actions), last 5 TT's view expandable for more. E.g. TON TT Non Technical TT Technical TT Other process TT
C53: Agent Approval view (If user is an approver), last 5 approval requests, expandable for more. e.g. 1. SIM swap approvals 2. Adjustment approval 3. Order Approval 4. TON Approvals 5. Fiber order approval
C54: Agent Notification view with drill down on order no., last 5 notification expandable for more. e.g. 1. MNP order rejection notification 2. SIM swap order rejection notification 3. Rejected TT notification 4. Rejected fiber order notification 5. Failed orders notification 6. Rejected adjustment requests
C55: Agent Lead history view, last 5 entries, includes pending and closed leads with below information. 1. Contact No. 2. Status 4. Closed by

Sheet Agent 360 References
A1: Agent 360 – Screen Reference
A3: Agent 360 Screen 1

Sheet Customer 360
A1: Customer 360 View – Channel Access Matrix
A2: One row per Customer 360 tile/component. Sub Details consolidate every visible option from the referenced screen; assign access by channel and record approval.
A4: Sequence | B4: View / Tile | C4: Component | D4: Sub Details | E4: Actions / Interaction | F4: Image Reference | G4: Telesales | H4: Call Center - Onshore | I4: Call Center - Offshore | J4: CMT - Mobile | K4: CMT - Fixed & Backoffice | L4: Business Care | M4: Collections & Billing | N4: Retail/Franchise (@GIRI) | O4: Direct Sales/Mass Market (@GIRI) | P4: EBU Sales (@TINA) | Q4: EBU Operations (@TINA) | R4: Business Justification | S4: Final Approval
A5: 1 | B5: Account Summary | C5: Context | D5: Breadcrumb: You are here: Account Summary | E5: Navigation context | F5: Screen 1
A6: 1 | B6: Account Summary | C6: Account Card | D6: Account name: Customer/account name displayed and truncated in the image Account Type: Business Customer Segment: Reimbursement Credit Limit Amount: 500 Account Status: Active Account Portal: Go to Account Portal link | E6: View account View Open account portal | F6: Screen 1 | H6: Read Only | I6: Read Only | K6: Read & Write
A7: 1 | B7: Account Summary | C7: Contact Card | D7: Whitelist Status: Whitelisted Qatari ID: ID value is partially masked in the image Date of Birth: 10/24/1996 Email: Email value is partially masked in the image Contact Portal: Go to Contact Portal link | E7: View Open contact portal | F7: Screen 1 | I7: Read Only | K7: Read & Write
A8: 1 | B8: Account Summary | C8: Installed Assets Preview | D8: Show All: Show All button Promotion: Postpaid Business Employee Plan Promotion Phone Number: Phone number is partially masked in the image Status: Active Search and paging: Search, record count, scroll and paging controls | E8: Show all assets Open promotion View Search or navigate records | F8: Screen 1 | I8: Read Only | K8: Read & Write
A9: 1–2 | B9: Customer 360 Tabs | C9: Tab | D9: Account Summary: Account Summary tab Asset Summary: Asset Summary tab | E9: Switch view | F9: Screen 1–2 | K9: Read & Write
A10: 1–2 | B10: Workflow Banner | C10: Status | D10: Pending Actions: No pending actions. | E10: View | F10: Screen 1–2 | K10: Read & Write
A11: 1–2 | B11: Workflow Banner | C11: Controls | D11: Previous / Next / Done: Workflow navigation buttons shown disabled | E11: Navigate workflow | F11: Screen 1–2 | K11: Read & Write
A12: 1,4–8 | B12: Activity Timeline | C12: Panel | D12: Timeline entries: Date, time, activity subject and message preview are displayed | E12: Open activity | F12: Screen 1,4–8 | K12: View Only
A13: 1,4–8 | B13: Activity Timeline | C13: Controls | D13: List view: List icon Add: Plus icon Show Later / Show Earlier: Timeline expansion controls | E13: Change timeline view Add activity Navigate timeline | F13: Screen 1,4–8 | K13: Read & Write
A14: 1,4–8 | B14: Summary Cards | C14: Orders | D14: Total Orders: 92 Open Orders: 0 Suspended Orders: 0 | E14: Open orders list Filter open orders Filter suspended orders | F14: Screen 1,4–8 | K14: Read Only
A15: 1,4–8 | B15: Summary Cards | C15: Trouble Tickets | D15: Total Trouble Tickets: 75 Open Tickets: 2 High Priority Tickets: 2 | E15: Open ticket list Filter open tickets Filter high-priority tickets | F15: Screen 1,4–8 | K15: Read & Write
A16: 1,4–8 | B16: Summary Cards | C16: Installed Assets | D16: Total Installed Assets: 1 | E16: Open installed-assets list | F16: Screen 1,4–8 | K16: Read & Write
A17: 1,4–8 | B17: Summary Cards | C17: Billing Profiles | D17: Total Billing Profiles: 3 Active Billing Profiles: 3 Suspended Billing Profiles: 1/0/1900 | E17: Open billing-profiles list Filter active profiles Filter suspended profiles | F17: Screen 1,4–8 | K17: View Only
A18: 1,4 | B18: All Orders | C18: Grid Field | D18: Status: Order status Order Date: Order date and time Type: Order type Order #: Order identifier displayed as a link MSISDN #: MSISDN value; partially masked in the image Journey: Journey field | E18: View or filter View or sort Open order View | F18: Screen 1,4 | K18: Read & Write
A19: 2 | B19: Asset Summary | C19: Recent Usage | D19: Usage filters: All, SMS, Data, Voice, Recharge Usage records: Usage type icon, country, date/time, usage amount and unit | E19: Filter usage View usage | F19: Screen 2 | K19: Read Only
A20: 2 | B20: Asset Summary | C20: Usage & Billing | D20: View Bills: View Bills button Voice: Voice button Data: Data button Charge: QR 0 Discount: QR 0 Net Amount: QR 0 | E20: Open bills View voice usage View data usage View | F20: Screen 2 | K20: Read & Write
A21: 2 | B21: Asset Summary | C21: Allowance | D21: Bill Manager 1: Remaining 0 QAR; expires 30-SEP-2026 Bill Manager 2: Remaining 0 QAR; expires 30-SEP-2026 International Minutes: Remaining 478 MINUTES; expires 30-SEP-2026 | E21: View allowance | F21: Screen 2 | K21: Read Only
A22: 2 | B22: Asset Summary | C22: Plan Card | D22: Promotion / Plan: Postpaid Business Employee Plan (name truncated in image) Phone Number: Phone number is partially masked in the image Service Type: Postpaid Business Bill Limit: 0.01 Change Limit: Change Limit button Activation Date: 4/28/2025 Postpaid Activation Date: 4/28/2025 Add-ons: SIM Card; Business Bill Limit; Bill Manager; Business Employee Plan; Mobile Voicemail; 4 Pass Access; CNAP; Optout MSB Manage Add Ons: Manage Add Ons button Upgrade Promotion: Upgrade Promotion button | E22: Open promotion View Change bill limit Manage add-ons Upgrade promotion | F22: Screen 2 | K22: Read & Write
A23: 3 | B23: Next Best Offer | C23: Panel | D23: Offer message: There are no more offers to display... | E23: View | F23: Screen 3 | K23: NA
A24: 3 | B24: Next Best Offer | C24: Controls | D24: Accept: Accept button shown disabled Reject: Reject button shown disabled Interested: Interested button shown disabled | E24: Accept offer Reject offer Mark interested | F24: Screen 3 | K24: NA
A25: 5 | B25: All Orders | C25: Grid Field | D25: Status: Visible examples are Complete Order Date: Visible order dates/times range from 2020 to 2023 Type: Sales Order Order #: Order identifiers displayed as links MSISDN #: Values are partially masked in the image Journey: Journey field is blank in visible rows | E25: View or filter View or sort Open order View | F25: Screen 5 | K25: Read & Write
A26: 5 | B26: All Orders | C26: Grid Controls | D26: Create / Delete / Search: Plus, trash and search icons Pagination: Record count and first/previous/next/last controls | E26: Create, delete or search Navigate records | F26: Screen 5 | K26: Read & Write
A27: 6 | B27: All Trouble Tickets | C27: Grid Field | D27: Status: Visible examples: Closed and Open Priority: Visible examples: 3-Medium, 2-High and 1-ASAP Sub Area: Visible examples: Mobile Broadband, OSM Provisioning ABC and Other Opened Date: Opened date and time Ticket ID #: Ticket identifiers displayed as links | E27: View or filter View or sort Open ticket | F27: Screen 6 | K27: Read & Write
A28: 6 | B28: All Trouble Tickets | C28: Grid Controls | D28: Create / Delete / Search: Plus, trash and search icons Pagination: Record count and first/previous/next/last controls | E28: Create, delete or search Navigate records | F28: Screen 6 | K28: Read & Write
A29: 7 | B29: All Installed Assets | C29: Grid Field | D29: Asset #: Asset identifier Service ID: Service identifier; partially masked in the image Service Account: Customer/service account name shown truncated Product Type: Visible examples: Promotion and Service Bundle Product: Postpaid Business Employee Plan and Mobile Service Bundle displayed as links Installed Date: 4/28/2025 Status: Active | E29: View Open service View or filter Open product View or sort | F29: Screen 7 | K29: Read & Write
A30: 7 | B30: All Installed Assets | C30: Grid Controls | D30: Create / Delete / Search: Plus, trash and search icons Pagination: Record count and first/previous/next/last controls | E30: Create, delete or search Navigate records | F30: Screen 7 | K30: Read & Write
... A32: 8 | B32: All Billing Profiles | C32: Grid Controls | D32: Create / Delete / Search: Plus, trash and search icons Pagination: Record count and first/previous/next/last controls | E32: Create, delete or search Navigate records | F32: Screen 8 | K32: NA

Sheet Customer 360 Screens
A1: 1
A39: 2
A77: 3
A83: 4
A121: 5
A159: 6
A197: 7
A235: 8

Sheet Sheet3
A1: To make the assessment easier for business users and management, add a Summary Dashboard sheet before the detailed access matrix.
A3: Sheet 1: Dashboard Summary
A5: Access Review Status
A7: Metric | B7: Count
A8: Total Views/Tabs Assessed | B8: 21
A9: Access Approved
A10: Access Rejected
A11: Read Only Access
A12: Read & Write Access
A13: Pending Review
A14: Total Channels Reviewed | B14: 9
A16: Channel-wise Access Summary
A18: Channel | B18: Total Eligible Views | C18: Read Only | D18: Read & Write | E18: Not Required | F18: Pending
A19: Onshore Sales
A20: Offshore Sales
A21: Retail
A22: Contact Center
A23: CMT Mobile
A24: CMT Fixed
A25: Team Leader
A26: Manager
A27: Back Office
A29: View Complexity Summary
A31: Category | B31: No. of Views
A32: Customer Information | B32: 4
A33: Service & Asset Management | B33: 3
A34: Orders Management | B34: 2
A35: Ticket Management | B35: 2
A36: Billing Management | B36: 2
A37: Sales & Prospecting | B37: 3
A38: Operational Management | B38: 5
A40: High-Risk Access Views
A42: View | B42: Customer Data | C42: Sensitive Data | D42: Approval Required
A43: Customer Profile | B43: Yes | C43: High | D43: Yes
A44: Billing Profiles | B44: Yes | C44: High | D44: Yes
A45: Recent Usage Dashboard | B45: Yes | C45: High | D45: Yes
A46: Blacklist Customers | B46: Yes | C46: High | D46: Yes
A47: Installed Assets | B47: Yes | C47: Medium | D47: Yes
A50: Sheet 2: Detailed Access Validation Matrix
A78: Recommended Dropdown Values
...

Sheet Sheet1

Sheet Customer360 Req Summary (2)
A1: Customer 360 – Channel Requirement Similarity Summary | AP1: Quick View
A2: Topics are normalized by meaning and ranked by channel coverage. Channel columns preserve the original requirement wording and update from the source sheet. | AP2: Drill Down
B3: Combine | C3: Merge
A5: Priority | B5: Consolidated Topic | C5: Channels | D5: Coverage | E5: Commonality | F5: Call Center - Onshore | G5: Telesales | H5: Call Center - Offshore | I5: CMT - Mobile | J5: CMT - Fixed & Backoffice | K5: Business Care | L5: Collections & Billing | M5: Retail/Franchise (@GIRI) | N5: Direct Sales/Mass Market (@GIRI) | O5: EBU Sales (@TINA) | P5: EBU Operations (@TINA) | Q5: View Categpory | R5: Source Row(s)2
A6: 1 | B6: Customer Snapshot & Verification (Contact Details & ID Status) | C6: =COUNTA(F6:L6) -> 7 | D6: =C6/7 -> 1 | E6: =IF(C6=7,"Common to all",IF(C6>=4,"High similarity",IF(C6>=2,"Shared","Unique"))) -> Common to all | F6: Customer Snapshot :Segment, preferred language, tenure, contact details, verification info Contact Details (Email, DOB, ID Status-Blacklisted/Whitelisted/In collection) Show the amount and the MSISDN responsible for the outstanding bill when a blacklisted account has multiple MSISDNs. | G6: Customer Snapshot :Segment, preferred language, tenure, contact details, verification info Contact Details (Email, DOB, ID Status-Blacklisted/Whitelisted/In collection) Show the amount and the MSISDN responsible for the outstanding bill when a blacklisted account has multiple MSISDNs. | H6: Customer Snapshot :Segment, preferred language, tenure, contact details, verification info Contact Details (Email, DOB, ID Status-Blacklisted/Whitelisted/In collection) Show the amount and the MSISDN responsible for the outstanding bill when a blacklisted account has multiple MSISDNs. | I6: Customer Snapshot :Segment, preferred language, tenure, contact details, verification info Contact Details (Email, DOB, ID Status-Blacklisted/Whitelisted/In collection) Show the amount and the MSISDN responsible for the outstanding bill when a blacklisted account has multiple MSISDNs. | J6: Customer Snapshot :Segment, preferred language, tenure, contact details, verification info Contact Details (Email, DOB, ID Status-Blacklisted/Whitelisted/In collection) Show the amount and the MSISDN responsible for the outstanding bill when a blacklisted account has multiple MSISDNs. | K6: Customer Snapshot :Segment, preferred language, tenure, contact details, verification info Contact Details (Email, DOB, ID Status-Blacklisted/Whitelisted/In collection) Show the amount and the MSISDN responsible for the outstanding bill when a blacklisted account has multiple MSISDNs. | L6: Customer Snapshot :Segment, preferred language, tenure, contact details, verification info Contact Details (Email, DOB, ID Status-Blacklisted/Whitelisted/In collection) Show the amount and the MSISDN responsible for the outstanding bill when a blacklisted account has multiple MSISDNs. | N6: N/A | Q6: Quick View | R6: 2
A7: 2 | B7: Account View & All Connections | C7: =COUNTA(F7:L7) -> 7 | D7: =C7/7 -> 1 | E7: =IF(C7=7,"Common to all",IF(C7>=4,"High similarity",IF(C7>=2,"Shared","Unique"))) -> Common to all | F7: Account View (Segment, Number of Connections and Service Type(All Connections :Total mobile/FBB/MBB/IoT lines), credit limit) | G7: Account View (Segment, Number of Connections and Service Type(All Connections :Total mobile/FBB/MBB/IoT lines), credit limit) | H7: Account View (Segment, Number of Connections and Service Type(All Connections :Total mobile/FBB/MBB/IoT lines), credit limit) | I7: Account View (Segment, Number of Connections and Service Type(All Connections :Total mobile/FBB/MBB/IoT lines), credit limit) | J7: Account View (Segment, Number of Connections and Service Type(All Connections :Total mobile/FBB/MBB/IoT lines), credit limit) | K7: Account View (Segment, Number of Connections and Service Type(All Connections :Total mobile/FBB/MBB/IoT lines), credit limit) | L7: Account View (Segment, Number of Connections and Service Type(All Connections :Total mobile/FBB/MBB/IoT lines), credit limit) | N7: N/A | Q7: Quick View | R7: 3
A8: 3 | B8: Billing Snapshot, Bills, Payments & Recharges (Billing View) | C8: =COUNTA(F8:L8) -> 7 | D8: =C8/7 -> 1 | E8: =IF(C8=7,"Common to all",IF(C8>=4,"High similarity",IF(C8>=2,"Shared","Unique"))) -> Common to all | F8: Billing Snapshot:Latest bill, outstanding balance, unbilled usage, due date, last payment, last recharge for prepaid | G8: Billing Snapshot:Latest bill, outstanding balance, unbilled usage, due date, last payment, last recharge for prepaid | H8: Billing Snapshot:Latest bill, outstanding balance, unbilled usage, due date, last payment, last recharge for prepaid | I8: Billing Snapshot:Latest bill, outstanding balance, unbilled usage, due date, last payment, last recharge for prepaid | J8: Billing Snapshot:Latest bill, outstanding balance, unbilled usage, due date, last payment, last recharge for prepaid | K8: Billing Snapshot:Latest bill, outstanding balance, unbilled usage, due date, last payment, last recharge for prepaid | L8: Billing Snapshot:Latest bill, outstanding balance, unbilled usage, due date, last payment, last recharge for prepaid | N8: N/A | Q8: Drill Down | R8: 7
A9: 4 | B9: Digital App View & Adoption | C9: =COUNTA(F9:L9) -> 7 | D9: =C9/7 -> 1 | E9: =IF(C9=7,"Common to all",IF(C9>=4,"High similarity",IF(C9>=2,"Shared","Unique"))) -> Common to all | F9: Digital App View (Recent Login, Active User) -Digital adoption % | G9: Digital App View (Recent Login, Active User) -Digital adoption % | H9: Digital App View (Recent Login, Active User) -Digital adoption % | I9: Digital App View (Recent Login, Active User) -Digital adoption % | J9: Digital App View (Recent Login, Active User) -Digital adoption % | K9: Digital App View (Recent Login, Active User) -Digital adoption % | L9: Digital App View (Recent Login, Active User) -Digital adoption % | N9: N/A | Q9: Quick View | R9: 8
A10: 6 | B10: Alerts & Risks | C10: =COUNTA(F10:L10) -> 7 | D10: =C10/7 -> 1 | E10: =IF(C10=7,"Common to all",IF(C10>=4,"High similarity",IF(C10>=2,"Shared","Unique"))) -> Common to all | F10: Alerts / Risks :Barring approaching, discount expiring, high usage, overdue TT, repeated contact | G10: Alerts / Risks :Barring approaching, discount expiring, high usage, overdue TT, repeated contact | H10: Alerts / Risks :Barring approaching, discount expiring, high usage, overdue TT, repeated contact | I10: Alerts / Risks :Barring approaching, discount expiring, high usage, overdue TT, repeated contact | J10: Alerts / Risks :Barring approaching, discount expiring, high usage, overdue TT, repeated contact | K10: Alerts / Risks :Barring approaching, discount expiring, high usage, overdue TT, repeated contact | L10: Alerts / Risks :Barring approaching, discount expiring, high usage, overdue TT, repeated contact | N10: N/A | Q10: Quick View | R10: 14
A11: 7 | B11: Dunning & Barring | C11: =COUNTA(F11:L11) -> 7 | D11: =C11/7 -> 1 | E11: =IF(C11=7,"Common to all",IF(C11>=4,"High similarity",IF(C11>=2,"Shared","Unique"))) -> Common to all | F11: Dunning & Barring :Current dunning stage, OG/IC barring dates, amount required, about to bared ,eligibility for PTT / About to be bared | G11: Dunning & Barring :Current dunning stage, OG/IC barring dates, amount required, about to bared ,eligibility for PTT / About to be bared | H11: Dunning & Barring :Current dunning stage, OG/IC barring dates, amount required, about to bared ,eligibility for PTT / About to be bared | I11: ='Requirements (Customer360)'!F9 -> Dunning & Barring :Current dunning stage, OG/IC barring dates, amount required, about to bared ,eligibility for PTT / About to be bared | J11: ='Requirements (Customer360)'!G9 -> Dunning & Barring :Current dunning stage, OG/IC barring dates, amount required, about to bared ,eligibility for PTT / About to be bared | K11: ='Requirements (Customer360)'!H9 -> Dunning & Barring :Current dunning stage, OG/IC barring dates, amount required, about to bared ,eligibility for PTT / About to be bared | L11: ='Requirements (Customer360)'!I9 -> Dunning & Barring :Current dunning stage, OG/IC barring dates, amount required, about to bared ,eligibility for PTT / About to be bared | N11: N/A | Q11: Drill Down | R11: 5, 9
A12: 8 | B12: Spend & Recharge Behavior | C12: =COUNTA(F12:L12) -> 4 | D12: =C12/7 -> 0.57142857 | E12: =IF(C12=7,"Common to all",IF(C12>=4,"High similarity",IF(C12>=2,"Shared","Unique"))) -> High similarity | G12: Spend :Monthly recurring charge, average bill/spend, recharge behavior for prepaid Postpaid: Monthly Revenue, Average Last 6 Months Revenue (based on Payments or Bills) Prepaid: Monthly Recharge Reveneue, Average 6 Months Revenue (Based on Recharge Values), Top Recharge Type: Combo, Data, Flex, Primary Balance | H12: ='Requirements (Customer360)'!E5 -> Spend :Monthly recurring charge, average bill/spend, recharge behavior for prepaid | J12: ='Requirements (Customer360)'!G5 -> Spend :Monthly recurring charge, average bill/spend, recharge behavior for prepaid | K12: ='Requirements (Customer360)'!H5 -> Spend :Monthly recurring charge, average bill/spend, recharge behavior for prepaid | N12: N/A | Q12: Quick View | R12: 5
A13: 9 | B13: Offers, Eligibility & Next Best Offer | C13: =COUNTA(F13:L13) -> 3 | D13: =C13/7 -> 0.42857143 | E13: =IF(C13=7,"Common to all",IF(C13>=4,"High similarity",IF(C13>=2,"Shared","Unique"))) -> Shared | F13: ='Requirements (Customer360)'!C9 -> Offers Visibility (DOI, Postpaid, New Fixed) | G13: =_xlfn.TEXTJOIN(CHAR(10),TRUE,'Requirements (Customer360)'!D6,'Requirements (Customer360)'!D12) -> Personalized Offers:CVM/targeted offers and eligible discounts Next Best Offer, DOI Eligibility, 2 months free eligibility on Gigahome offers (can show the activation date of the current active gigahome connection) | H13: =_xlfn.TEXTJOIN(CHAR(10),TRUE,'Requirements (Customer360)'!E9,'Requirements (Customer360)'!E12) -> Offers Visibility (DOI, Postpaid, New Fixed) Next Best Offer | N13: N/A | R13: 6, 9, 12
A14: 10 | B14: Recent Transactions & Changes | C14: =COUNTA(F14:L14) -> 3 | D14: =C14/7 -> 0.42857143 | E14: =IF(C14=7,"Common to all",IF(C14>=4,"High similarity",IF(C14>=2,"Shared","Unique"))) -> Shared | F14: Last Transactions View which should have all recent Purchased Add-ons or Changes Done in the MSISDN or Account, Ticket or Activities Audit Trial activity :Recent Interactions /recent Order actioned /Recent TT | G14: ='Requirements (Customer360)'!D10 -> Last Transactions View which should have all recent Purchased Add-ons or Changes Done in the MSISDN or Account, Ticket or Activities | H14: ='Requirements (Customer360)'!E6 -> Last Transactions View which should have all recent Purchased Add-ons or Changes Done in the MSISDN or Account, Ticket or Activities | N14: N/A | R14: 6, 10
A15: 11 | B15: Contact Details & ID Status | C15: =COUNTA(F15:L15) -> 3 | D15: =C15/7 -> 0.42857143 | E15: =IF(C15=7,"Common to all",IF(C15>=4,"High similarity",IF(C15>=2,"Shared","Unique"))) -> Shared | F15: ='Requirements (Customer360)'!C4 -> Contact Details (Email, DOB, ID Status-Blacklisted/Whitelisted) | G15: Contact Details (Email, DOB, ID Status-Blacklisted/Whitelisted/In collection) Show the amount and the MSISDN responsible for the outstanding bill when a blacklisted account has multiple MSISDNs. | H15: ='Requirements (Customer360)'!E4 -> Contact Details (Email, DOB, ID Status-Blacklisted/Whitelisted) | N15: N/A | R15: 4
A16: 12 | B16: Bell Icon & Bulk Notes | C16: =COUNTA(F16:L16) -> 2 | D16: =C16/7 -> 0.28571429 | E16: =IF(C16=7,"Common to all",IF(C16>=4,"High similarity",IF(C16>=2,"Shared","Unique"))) -> Shared | F16: ='Requirements (Customer360)'!C10 -> Bell Icon/Bulk Notes View | H16: ='Requirements (Customer360)'!E10 -> Bell Icon/Bulk Notes View | N16: N/A | R16: 10
A17: 13 | B17: Account Hierarchy | C17: =COUNTA(F17:L17) -> 1 | D17: =C17/7 -> 0.14285714 | E17: =IF(C17=7,"Common to all",IF(C17>=4,"High similarity",IF(C17>=2,"Shared","Unique"))) -> Unique | K17: ='Requirements (Customer360)'!H4 -> Account Hierarchy:Parent/child accounts, billing accounts and number of connections | N17: N/A | R17: 4
A18: 14 | B18: Authorized Contact | C18: =COUNTA(F18:L18) -> 1 | D18: =C18/7 -> 0.14285714 | E18: =IF(C18=7,"Common to all",IF(C18>=4,"High similarity",IF(C18>=2,"Shared","Unique"))) -> Unique | K18: =IFERROR(_xlfn.TEXTBEFORE(_xlfn.TEXTAFTER('Requirements (Customer360)'!H2,CHAR(10)),CHAR(10)),"") -> 2.Authorized Contact :Authorized person(s), role, mobile/email, authorization level | N18: N/A | R18: 2
A19: 15 | B19: Account Manager & Escalation Contact | C19: =COUNTA(F19:L19) -> 1 | D19: =C19/7 -> 0.14285714 | E19: =IF(C19=7,"Common to all",IF(C19>=4,"High similarity",IF(C19>=2,"Shared","Unique"))) -> Unique | K19: =IFERROR(_xlfn.TEXTAFTER('Requirements (Customer360)'!H2,CHAR(10),2),"") -> 3.AM name, mobile/email, backup AM, availability/escalation contact | N19: N/A | R19: 2
A20: 16 | B20: Repeated Call Alert | C20: =COUNTA(F20:L20) -> 1 | D20: =C20/7 -> 0.14285714 | E20: =IF(C20=7,"Common to all",IF(C20>=4,"High similarity",IF(C20>=2,"Shared","Unique"))) -> Unique | F20: ='Requirements (Customer360)'!C12 -> Repeated call alert, Ex : in case customer called twice same day.. | N20: N/A | R20: 12
A21: 17 | B21: Primary MSISDN Highlight | C21: =COUNTA(F21:L21) -> 1 | D21: =C21/7 -> 0.14285714 | E21: =IF(C21=7,"Common to all",IF(C21>=4,"High similarity",IF(C21>=2,"Shared","Unique"))) -> Unique | F21: ='Requirements (Customer360)'!C13 -> Highlight Primary MSISDN | N21: N/A | R21: 13
A22: 18 | B22: TNPS Rating History | C22: =COUNTA(F22:L22) -> 1 | D22: =C22/7 -> 0.14285714 | E22: =IF(C22=7,"Common to all",IF(C22>=4,"High similarity",IF(C22>=2,"Shared","Unique"))) -> Unique | G22: ='Requirements (Customer360)'!D13 -> history of customer's TNPS rating | N22: N/A | R22: 13
A23: 19 | B23: Plan, Limits, Add-ons & Plan Changes | C23: =COUNTA(F23:L23) -> 1 | D23: =C23/7 -> 0.14285714 | E23: =IF(C23=7,"Common to all",IF(C23>=4,"High similarity",IF(C23>=2,"Shared","Unique"))) -> Unique | H23: ='Requirements (Customer360)'!E13 -> Plan Name , Bill Limit , Credit Limit , Addon , Plan change details | N23: N/A | R23: 13
A24: 20 | B24: Orders, Trouble Tickets, Assets & Billing Profile Tabs | C24: =COUNTA(F24:L24) -> 1 | D24: =C24/7 -> 0.14285714 | E24: =IF(C24=7,"Common to all",IF(C24>=4,"High similarity",IF(C24>=2,"Shared","Unique"))) -> Unique | H24: ='Requirements (Customer360)'!E15 -> Orders, Trouble Tickets, Inastalled Assets , Billing Profile Tabs | N24: N/A | R24: 15
B25: MSISDIN Visbility count | C25: 1 | D25: =C25/7 -> 0.14285714 | E25: =IF(C25=7,"Common to all",IF(C25>=4,"High similarity",IF(C25>=2,"Shared","Unique"))) -> Unique
B26: Assets View | C26: =COUNTA(F26:L26) -> 1 | D26: =C26/7 -> 0.14285714 | E26: =IF(C26=7,"Common to all",IF(C26>=4,"High similarity",IF(C26>=2,"Shared","Unique"))) -> Unique | F26: active, barred, suspended, pending/Existing Discounts, expiry date, promotional benefits, Highlight Primary MSISDN

Sheet Customer 360 References
A1: Customer 360 – Screen References
A3: Screen 1
A25: Screen 2
A47: Screen 3
A58: Screen 4
A80: Screen 5
A102: Screen 6
A124: Screen 7
A146: Screen 8

Sheet Table View
A1: ## | B1: Tile | C1: Details in Tile | D1: Dril Down or Select Feature View | E1: Dril Down
A2: # | B2: Customer Verification
A3: 1 | C3: First & Last Name
A4: 2 | C4: ID Number
A5: 3 | C5: Email
A6: 4 | C6: Phone
A7: 5 | C7: DOB (Date of Birth)
A8: 6 | C8: Blacklist Status | D8: Drill Down
A9: 7 | D9: Blacklisted
A10: 8 | D10: Account Number | E10: Drill Down
A11: 9 | D11: Total amount
A12: 10 | D12: Bill Period
A13: 11 | D13: Bill Number
A14: 12 | D14: MSISDNs
A15: 13 | C15: Offers
A16: 14 | C16: Contact Hirerarchy | D16: Drill Down
A17: 15 | D17: First & Last Name | E17: Drill Down
A18: 16 | D18: ID Number
A19: 17 | D19: Email
A20: 18 | D20: Phone
A21: 19 | D21: DOB (Date of Birth)
A22: 20 | D22: Blacklist Status
A23: 21 | D23: Contact Role
A24: # | B24: Account Information
A25: 1 | C25: Account Name
A26: 2 | C26: Account Number
A27: 3 | C27: Customer Type
A28: 4 | C28: Segment
A29: 5 | C29: Credit Limit
A30: 6 | C30: Total Number of Connection Count (Service Type wise) Fixed, Mobile, IOT, etc
A31: 7 | C31: Agent ID & Email
A32: 8 | C32: Primary MSISDN
A33: 9 | C33: Postpaid: Monthly Revenue, Average Last 6 Months Revenue (based on Payments or Bills)
A34: 10 | C34: Prepaid: Monthly Recharge Reveneue, Average 6 Months Revenue (Based on Recharge Values), Top Recharge Type: Combo, Data, Flex, Primary Balance
A35: 11 | C35: Account Hirerarchy | D35: Drill Down
A36: 12 | D36: Account Name
A37: 13 | D37: Account Number
A38: 14 | D38: Customer Type
A39: 15 | D39: Segment
A40: 16 | D40: Credit Limit
...

Sheet List view
A2: Customer Verification
B3: First & Last Name
B4: ID Number
B5: Email
B6: Phone
B7: DOB (Date of Birth)
B8: Blacklist Status
B9: Offers
A10: Account Information
B11: Account Name
B12: Account Number
B13: Customer Type
B14: Segment
B15: Credit Limit
B16: Total Number of Connection Count (Service Type wise) Fixed, Mobile, IOT, etc
B17: Agent ID
B18: Primary MSISDN
A19: Alert/Bulk Note
B20: Next <> Previous
A21: Assets View
B22: Filter (Service Type/Plan)
B23: MSISDN | C23: Current Balance | D23: Barrings
B24: Plan
B25: Status
B26: Bill Limit
B27: Discount
B28: Customer Since
B29: Postpaid Activation Date
B30: Plan Activation Date
B31: Discount Expiry Date
B32: Drill Down Attributes
B33: Dill Down MSISDN Level Offers
A34: Billing View
B35: Billing Profile (Name) | C35: Postpaid | D35: Total Due Amount | E35: Last Billed Amount | F35: Last Payment | G35: Last Payment Date
B36: Bill Cycle
B37: Bill Email
B38: Bill Type (Detail or Summary)
B39: Drill Down Attributes Select Billing Profile
A40: Drill Down Attributes Select Billing Profile

Sheet Sheet5
A3: Count of Details | B3: Column Labels
A4: Topic | B4: Drill Down or Select | C4: Real Time | D4: Total
A5: Assets | B5: 26 | C5: 1 | D5: 27
A6: Account Information | B6: 19 | C6: 7 | D6: 26
A7: Contact Information | B7: 7 | C7: 8 | D7: 15
A8: Billing & Payments | B8: 11 | D8: 11
A9: Account Address | B9: 4 | C9: 4 | D9: 8
A10: Contact/Assets Information | B10: 3 | C10: 2 | D10: 5
A11: Account/Contact Lead | C11: 5 | D11: 5
A12: Menu | B12: 1 | D12: 1
A13: Alert & Risks | C13: 1 | D13: 1
A14: Audit Trail | B14: 1 | D14: 1
A15: Total | B15: 72 | C15: 28 | D15: 100

Sheet Sheet2
A3: Count of # | B3: Column Labels
A4: Row Labels | B4: Real Time | C4: Side Bar Menu | D4: Grand Total
A5: Queue | C5: 1 | D5: 1
A6: Filter Option with Queue Name & Type of Transaction Order, Activity, Request,Etc | C6: 1 | D6: 1
A7: Order Approver | B7: 1 | D7: 1
A8: Filter Options - Auto-Default My Team Approval Orders with 7 days date range 1. Order ID 2. Order Type 3. Order Sub-Type 4. Created By 5. Order Created on 7. Order Stauts 8. MSISDN | B8: 1 | D8: 1
A9: Trouble Tickets Dashboard | B9: 1 | D9: 1
A10: Filter Options - Auto-Default My All tickets with 7Days Date Range Fields: 1. Ticket ID 2. Ticket Stauts 3. Created on 4. Ticket Area 5. Ticket Sub-Area 6.MSISDN | B10: 1 | D10: 1
A11: Adjustments | B11: 1 | D11: 1
A12: Filter Options - Auto-Default My Adjustments with 7 days date range 1. Request ID 2. Request Date & Time 3. Adjustment Type 4. Adjustment Sub-Type 5. Reason for Request 7. Created By 8. MSISDN 9.Account 10. Billing Profile 11. Adjustment Value 11. Owner (who Approved/Rejected) | B12: 1 | D12: 1
A13: Order Tasks | B13: 1 | D13: 1
A14: Filter Options - Auto-Default My All Orders Task with 7 days date range 1. Order ID 2. Order Type 3. Order Sub-Type 4. Created By 5. Order Created on 6. Task Type 7. Order Stauts 8. MSISDN 9.Task Age 10. Task Assigned To | B14: 1 | D14: 1
A15: FDO Requests | B15: 1 | D15: 1
A16: Filter Options - Auto-Default My FDO Request with 7 days date range 1. FDO Request ID 2. Request Type 3. Request Sub-Type 4. Created By 5. Order Created on 6. Actual Execution DateTime 7. Request Status 8. MSISDN 9.Siebel Order ID 10. Reason | B16: 1 | D16: 1
A17: Sales Order | B17: 1 | D17: 1
A18: Filter Options - Auto-Default My All Orders with 7Days Date Range 1. Order ID 2. Order Type 3. Order Sub-Type 4. Created By 5. Order Created on 6. Completed By 7. Order Stauts 8. MSISDN | B18: 1 | D18: 1
... A24: Filter Options - Auto-Default My TNPS with 7 days date range 1. MSISDN 2. Date & Time 3. Response Type (Promoter, Passive,Detractor,Neutral) | B24: 1 | D24: 1
A25: Grand Total | B25: 9 | C25: 1 | D25: 10

Sheet Premium Agent
A1: # | B1: Sequencing | C1: Component | D1: TOPIC | E1: Details | F1: Premium Agent | AX1: Real Time | AY1: Drill Down or Select | AZ1: N/A
A2: 1 | C2: Account | D2: Account Information | E2: Primary MSISDN | F2: Real Time
A3: 2 | C3: Account | D3: Account Information | E3: AM name | F3: Drill Down or Select
A4: 3 | C4: Account | D4: Account Information | E4: AM mobile | F4: Drill Down or Select
A5: 4 | C5: Account | D5: Account Information | E5: AM Email | F5: Drill Down or Select
A6: 5 | C6: Account | D6: Account Information | E6: Manager Email | F6: Drill Down or Select
A7: 6 | C7: Account | D7: Account Information | E7: Availability/escalation contact | F7: Drill Down or Select
A8: 7 | C8: Account | D8: Account Information | E8: Segment | F8: Real Time
A9: 8 | C9: Account | D9: Account Information | E9: Service Type Number of Connections (Total Per Account + Total Per Plan Type) | F9: Real Time
A10: 9 | C10: Account | D10: Account Information | E10: Account Hierarchy | F10: Drill Down or Select
A11: 10 | C11: Account | D11: Account Information | E11: Billing Email ID (It should show all the email Ids which are marked for Billing Receipent) | F11: Real Time
A12: 11 | C12: Account | D12: Billing & Payments | E12: Postpaid - Monthly Recurring Charge | F12: Drill Down or Select
A13: 12 | C13: Account | D13: Billing & Payments | E13: Postpaid - Average Bill/Spend | F13: Drill Down or Select
... A102: 101 | C102: Lead | D102: Account/Contact Lead | E102: Lead Status | F102: Real Time
D103: Penalty View | E103: Star number Penalty | F103: Drill Down or Select
D104: Penalty View | E104: Device Penalty (Fiber & 5G) | F104: Drill Down or Select
D105: Account Information | E105: Pending TON requests | F105: Real Time
D106: Assets | E106: Lifestyle Benifits | F106: Drill Down or Select
D107: Contact Information | E107: Cross sale offers flag | F107: Drill Down or Select
D108: Account Information | E108: Pending Adjustments | F108: Real Time
D109: Account Information | E109: Pending Sim swap | F109: Real Time
D110: Assets | E110: Notifications & SMS | F110: Drill Down or Select
D111: Contact Information | E111: ID Type | F111: Real Time
D112: Contact Information | E112: ID Number | F112: Real Time
D113: Assets | E113: Sim serial | F113: Real Time
D114: Assets | E114: Star number value | F114: Real Time
... D123: Contact Information | E123: Credit Score | F123: Real Time
D124: EBU | E124: Contract start and end date
E125: Product wise revenue split
E126: ZSB to be mandatory for business activations and data to be imported from Dynamics

Sheet Retail Sales Agent
A1: # | B1: Sequencing | C1: Component | D1: TOPIC | E1: Details | F1: Retail Sales Agent | AX1: Real Time | AY1: Drill Down or Select | AZ1: N/A
A2: 86 | C2: Open UI Address | D2: Account Address | E2: RFS Flag (Y/N) | F2: Real Time
A3: 90 | C3: National Address | D3: Account Address | E3: RFS Flag (Y/N) | F3: Real Time
A4: 1 | C4: Account | D4: Account Information | E4: Primary MSISDN | F4: Real Time
A5: 7 | C5: Account | D5: Account Information | E5: Segment | F5: Real Time
A6: 22 | C6: Account | D6: Account Information | E6: OG/IC Barring Dates | F6: Real Time
A7: 26 | C7: Account | D7: Account Information | E7: Credit Limit | F7: Real Time
A8: 27 | C8: Account | D8: Account Information | E8: Overdue TT | F8: Real Time
D9: Account Information | E9: Pending TON requests | F9: Real Time
D10: Account Information | E10: Actiivity (last 5) | F10: Real Time
D11: Account Information | E11: Last 5 Orders | F11: Real Time
D12: Account Information | E12: Actiivity (last 5) | F12: Real Time
D13: Account Information | E13: Special Management | F13: Real Time
D14: Account Information | E14: NAS/Address | F14: Real Time
A15: 96 | C15: Account/Contact/Asset | D15: Activation/Modification Side Bar | E15: Existing Customer New Activation or Migration Journey - Based on Offers (Cross Sales, Sales App, AutoBase, Migration, Happy Offer) or Standalone trigger Option for Guided Journey | F15: Real Time
A16: 35 | C16: Assets | D16: Assets | E16: MSISDN Status (Active, Suspended, Barred) | F16: Real Time
A17: 36 | C17: Assets | D17: Assets | E17: Pending Discounts | F17: Real Time
A18: 37 | C18: Assets | D18: Assets | E18: Existing Discounts Expiry Date | F18: Real Time
A19: 39 | C19: Assets | D19: Assets | E19: Any Barring Flags | F19: Real Time
A20: 40 | C20: Assets | D20: Assets | E20: MSISDN Activation Date | F20: Real Time
A21: 41 | C21: Assets | D21: Assets | E21: Postpaid Activation Date | F21: Real Time
A22: 42 | C22: Assets | D22: Assets | E22: Plan Activation Date | F22: Real Time
A23: 44 | C23: Assets | D23: Assets | E23: Plan Name | F23: Real Time
A24: 94 | C24: Existing DOI View | D24: Assets | E24: DOI Remaining Amount | F24: Real Time
A25: 95 | C25: Existing DOI View | D25: Assets | E25: DOI Tennure | F25: Real Time
D26: Assets | E26: Sim serial | F26: Real Time
D27: Assets | E27: Star number value | F27: Real Time
D28: Assets | E28: Autobase elegibility flag | F28: Real Time
A29: 17 | C29: Account | D29: Billing & Payments | E29: Outstanding Balance | F29: Real Time
A30: 19 | C30: Account | D30: Billing & Payments | E30: Due Date | F30: Real Time
A31: 23 | C31: Account | D31: Billing & Payments | E31: Amount Required to Pay | F31: Real Time
A32: 49 | C32: Blacklist ID Status | D32: Blacklist View | E32: Blacklisted ID Status | F32: Real Time
A33: 50 | C33: Blacklist ID Status | D33: Blacklist View | E33: Account Number | F33: Real Time
A34: 54 | C34: Blacklist ID Status | D34: Blacklist View | E34: MSISDNs | F34: Real Time
A35: 55 | C35: Contact | D35: Contact Information | E35: ID Number | F35: Real Time
A36: 56 | C36: Contact | D36: Contact Information | E36: ID Status (Blacklisted/Whitelisted) | F36: Real Time
A37: 57 | C37: Contact | D37: Contact Information | E37: Preferred Language | F37: Real Time
A38: 58 | C38: Contact | D38: Contact Information | E38: Tennure | F38: Real Time
A39: 59 | C39: Contact | D39: Contact Information | E39: First Name & Last Name (Full Name) | F39: Real Time
A40: 60 | C40: Contact | D40: Contact Information | E40: Email | F40: Real Time
...

Sheet Telesales Agent
A1: # | B1: Sequencing | C1: Component | D1: TOPIC | E1: Details | F1: Telesales Agent | AX1: Real Time | AY1: Drill Down or Select | AZ1: N/A
A2: 1 | C2: Account | D2: Account Information | E2: Primary MSISDN | F2: Real Time
A3: 2 | C3: Account | D3: Account Information | E3: AM name | F3: Drill Down or Select
A4: 3 | C4: Account | D4: Account Information | E4: AM mobile | F4: Drill Down or Select
A5: 4 | C5: Account | D5: Account Information | E5: AM Email | F5: Drill Down or Select
A6: 5 | C6: Account | D6: Account Information | E6: Manager Email | F6: Drill Down or Select
A7: 6 | C7: Account | D7: Account Information | E7: Availability/escalation contact | F7: Drill Down or Select
A8: 7 | C8: Account | D8: Account Information | E8: Segment | F8: Real Time
A9: 8 | C9: Account | D9: Account Information | E9: Service Type Number of Connections (Total Per Account + Total Per Plan Type) | F9: Real Time
A10: 9 | C10: Account | D10: Account Information | E10: Account Hierarchy | F10: Drill Down or Select
A11: 10 | C11: Account | D11: Account Information | E11: Billing Email ID (It should show all the email Ids which are marked for Billing Receipent) | F11: Real Time
A12: 11 | C12: Account | D12: Billing & Payments | E12: Postpaid - Monthly Recurring Charge | F12: Real Time
A13: 12 | C13: Account | D13: Billing & Payments | E13: Postpaid - Average Bill/Spend | F13: Real Time
... A102: 101 | C102: Lead | D102: Account/Contact Lead | E102: Lead Status | F102: Real Time
D103: Penalty View | E103: Star number Penalty | F103: Drill Down or Select
D104: Penalty View | E104: Device Penalty (Fiber & 5G) | F104: Drill Down or Select
D105: Account Information | E105: Pending TON requests | F105: Real Time
D106: Assets | E106: Lifestyle Benifits | F106: Drill Down or Select
D107: Contact Information | E107: Cross sale offers flag | F107: Drill Down or Select
D108: Account Information | E108: Pending Adjustments | F108: Real Time
D109: Account Information | E109: Pending Sim swap | F109: Real Time
D110: Assets | E110: Notifications & SMS | F110: Drill Down or Select
D111: Contact Information | E111: ID Type | F111: Real Time
D112: Contact Information | E112: ID Number | F112: Real Time
D113: Assets | E113: Sim serial | F113: Real Time
D114: Assets | E114: Star number value | F114: Real Time
... D123: Contact Information | E123: Credit Score | F123: Real Time
D124: EBU | E124: Contract start and end date
E125: Product wise revenue split
E126: ZSB to be mandatory for business activations and data to be imported from Dynamics

Sheet Customer Care Agent
A1: # | B1: Sequencing | C1: Component | D1: TOPIC | E1: Details | F1: Customer Care Agent | AX1: Real Time | AY1: Drill Down or Select | AZ1: N/A
A2: 1 | C2: Account | D2: Account Information | E2: Primary MSISDN | F2: Real Time
A3: 2 | C3: Account | D3: Account Information | E3: AM name | F3: Drill Down or Select
A4: 3 | C4: Account | D4: Account Information | E4: AM mobile | F4: Drill Down or Select
A5: 4 | C5: Account | D5: Account Information | E5: AM Email | F5: Drill Down or Select
A6: 5 | C6: Account | D6: Account Information | E6: Manager Email | F6: Drill Down or Select
A7: 6 | C7: Account | D7: Account Information | E7: Availability/escalation contact | F7: Drill Down or Select
A8: 7 | C8: Account | D8: Account Information | E8: Segment | F8: Real Time
A9: 8 | C9: Account | D9: Account Information | E9: Service Type Number of Connections (Total Per Account + Total Per Plan Type) | F9: Real Time
A10: 9 | C10: Account | D10: Account Information | E10: Account Hierarchy | F10: Drill Down or Select
A11: 10 | C11: Account | D11: Account Information | E11: Billing Email ID (It should show all the email Ids which are marked for Billing Receipent) | F11: Real Time
A12: 11 | C12: Account | D12: Billing & Payments | E12: Postpaid - Monthly Recurring Charge | F12: Drill Down or Select
A13: 12 | C13: Account | D13: Billing & Payments | E13: Postpaid - Average Bill/Spend | F13: Drill Down or Select
... A102: 101 | C102: Lead | D102: Account/Contact Lead | E102: Lead Status | F102: Real Time
D103: Penalty View | E103: Star number Penalty | F103: Drill Down or Select
D104: Penalty View | E104: Device Penalty (Fiber & 5G) | F104: Drill Down or Select
D105: Account Information | E105: Pending TON requests | F105: Real Time
D106: Assets | E106: Lifestyle Benifits | F106: Drill Down or Select
D107: Contact Information | E107: Cross sale offers flag | F107: Drill Down or Select
D108: Account Information | E108: Pending Adjustments | F108: Real Time
D109: Account Information | E109: Pending Sim swap | F109: Real Time
D110: Assets | E110: Notifications & SMS | F110: Drill Down or Select
D111: Contact Information | E111: ID Type | F111: Real Time
D112: Contact Information | E112: ID Number | F112: Real Time
D113: Assets | E113: Sim serial | F113: Real Time
D114: Assets | E114: Star number value | F114: Real Time
... D124: EBU | E124: Contract start and end date | F124: Drill Down or Select
E125: Product wise revenue split
E126: ZSB to be mandatory for business activations and data to be imported from Dynamics

Sheet Complaints Agent
A1: # | B1: Sequencing | C1: Component | D1: TOPIC | E1: Details | F1: Complaints Agent | AX1: Real Time | AY1: Drill Down or Select | AZ1: N/A
A2: 1 | C2: Account | D2: Account Information | E2: Primary MSISDN | F2: Real Time
A3: 2 | C3: Account | D3: Account Information | E3: AM name | F3: Drill Down or Select
A4: 3 | C4: Account | D4: Account Information | E4: AM mobile | F4: Drill Down or Select
A5: 4 | C5: Account | D5: Account Information | E5: AM Email | F5: Drill Down or Select
A6: 5 | C6: Account | D6: Account Information | E6: Manager Email | F6: Drill Down or Select
A7: 6 | C7: Account | D7: Account Information | E7: Availability/escalation contact | F7: Drill Down or Select
A8: 7 | C8: Account | D8: Account Information | E8: Segment | F8: Real Time
A9: 8 | C9: Account | D9: Account Information | E9: Service Type Number of Connections (Total Per Account + Total Per Plan Type) | F9: Real Time
A10: 9 | C10: Account | D10: Account Information | E10: Account Hierarchy | F10: Drill Down or Select
A11: 10 | C11: Account | D11: Account Information | E11: Billing Email ID (It should show all the email Ids which are marked for Billing Receipent) | F11: Real Time
A12: 11 | C12: Account | D12: Billing & Payments | E12: Postpaid - Monthly Recurring Charge | F12: Drill Down or Select
A13: 12 | C13: Account | D13: Billing & Payments | E13: Postpaid - Average Bill/Spend | F13: Drill Down or Select
... A102: 101 | C102: Lead | D102: Account/Contact Lead | E102: Lead Status | F102: Real Time
D103: Penalty View | E103: Star number Penalty | F103: Drill Down or Select
D104: Penalty View | E104: Device Penalty (Fiber & 5G) | F104: Drill Down or Select
D105: Account Information | E105: Pending TON requests | F105: Real Time
D106: Assets | E106: Lifestyle Benifits | F106: Drill Down or Select
D107: Contact Information | E107: Cross sale offers flag | F107: Drill Down or Select
D108: Account Information | E108: Pending Adjustments | F108: Real Time
D109: Account Information | E109: Pending Sim swap | F109: Real Time
D110: Assets | E110: Notifications & SMS | F110: Drill Down or Select
D111: Contact Information | E111: ID Type | F111: Real Time
D112: Contact Information | E112: ID Number | F112: Real Time
D113: Assets | E113: Sim serial | F113: Real Time
D114: Assets | E114: Star number value | F114: Real Time
... D123: Contact Information | E123: Credit Score | F123: Drill Down or Select
D124: EBU | E124: Contract start and end date
E125: Product wise revenue split
E126: ZSB to be mandatory for business activations and data to be imported from Dynamics

Sheet Business Care Agent
A1: # | B1: Sequencing | C1: Component | D1: TOPIC | E1: Details | F1: Business Care Agent | AX1: Real Time | AY1: Drill Down or Select | AZ1: N/A
A2: 1 | C2: Account | D2: Account Information | E2: Primary MSISDN | F2: Real Time
A3: 2 | C3: Account | D3: Account Information | E3: AM name | F3: Real Time
A4: 3 | C4: Account | D4: Account Information | E4: AM mobile | F4: Real Time
A5: 4 | C5: Account | D5: Account Information | E5: AM Email | F5: Real Time
A6: 5 | C6: Account | D6: Account Information | E6: Manager Email | F6: Real Time
A7: 6 | C7: Account | D7: Account Information | E7: Availability/escalation contact | F7: Drill Down or Select
A8: 7 | C8: Account | D8: Account Information | E8: Segment | F8: Real Time
A9: 8 | C9: Account | D9: Account Information | E9: Service Type Number of Connections (Total Per Account + Total Per Plan Type) | F9: Real Time
A10: 9 | C10: Account | D10: Account Information | E10: Account Hierarchy | F10: Real Time
A11: 10 | C11: Account | D11: Account Information | E11: Billing Email ID (It should show all the email Ids which are marked for Billing Receipent) | F11: Real Time
A12: 11 | C12: Account | D12: Billing & Payments | E12: Postpaid - Monthly Recurring Charge | F12: Real Time
A13: 12 | C13: Account | D13: Billing & Payments | E13: Postpaid - Average Bill/Spend | F13: Real Time
... A102: 101 | C102: Lead | D102: Account/Contact Lead | E102: Lead Status | F102: Real Time
D103: Penalty View | E103: Star number Penalty | F103: Drill Down or Select
D104: Penalty View | E104: Device Penalty (Fiber & 5G) | F104: Drill Down or Select
D105: Account Information | E105: Pending TON requests | F105: Real Time
D106: Assets | E106: Lifestyle Benifits | F106: Drill Down or Select
D107: Contact Information | E107: Cross sale offers flag | F107: Drill Down or Select
D108: Account Information | E108: Pending Adjustments | F108: Real Time
D109: Account Information | E109: Pending Sim swap | F109: Real Time
D110: Assets | E110: Notifications & SMS | F110: Drill Down or Select
D111: Contact Information | E111: ID Type | F111: Real Time
D112: Contact Information | E112: ID Number | F112: Real Time
D113: Assets | E113: Sim serial | F113: Real Time
D114: Assets | E114: Star number value | F114: Real Time
... D123: Contact Information | E123: Credit Score | F123: Drill Down or Select
D124: EBU | E124: Contract start and end date
E125: Product wise revenue split
E126: ZSB to be mandatory for business activations and data to be imported from Dynamics

Sheet Credit Control Agent
A1: # | B1: Sequencing | C1: Component | D1: TOPIC | E1: Details | F1: Credit Control Agent | AX1: Real Time | AY1: Drill Down or Select | AZ1: N/A
A2: 1 | C2: Account | D2: Account Information | E2: Primary MSISDN | F2: Real Time
A3: 2 | C3: Account | D3: Account Information | E3: AM name | F3: Drill Down or Select
A4: 3 | C4: Account | D4: Account Information | E4: AM mobile | F4: Drill Down or Select
A5: 4 | C5: Account | D5: Account Information | E5: AM Email | F5: Drill Down or Select
A6: 5 | C6: Account | D6: Account Information | E6: Manager Email | F6: Drill Down or Select
A7: 6 | C7: Account | D7: Account Information | E7: Availability/escalation contact | F7: Drill Down or Select
A8: 7 | C8: Account | D8: Account Information | E8: Segment | F8: Real Time
A9: 8 | C9: Account | D9: Account Information | E9: Service Type Number of Connections (Total Per Account + Total Per Plan Type) | F9: Real Time
A10: 9 | C10: Account | D10: Account Information | E10: Account Hierarchy | F10: Drill Down or Select
A11: 10 | C11: Account | D11: Account Information | E11: Billing Email ID (It should show all the email Ids which are marked for Billing Receipent) | F11: Real Time
A12: 11 | C12: Account | D12: Billing & Payments | E12: Postpaid - Monthly Recurring Charge | F12: Drill Down or Select
A13: 12 | C13: Account | D13: Billing & Payments | E13: Postpaid - Average Bill/Spend | F13: Drill Down or Select
... A102: 101 | C102: Lead | D102: Account/Contact Lead | E102: Lead Status | F102: Real Time
D103: Penalty View | E103: Star number Penalty | F103: Drill Down or Select
D104: Penalty View | E104: Device Penalty (Fiber & 5G) | F104: Drill Down or Select
D105: Account Information | E105: Pending TON requests | F105: Real Time
D106: Assets | E106: Lifestyle Benifits | F106: Drill Down or Select
D107: Contact Information | E107: Cross sale offers flag | F107: Drill Down or Select
D108: Account Information | E108: Pending Adjustments | F108: Real Time
D109: Account Information | E109: Pending Sim swap | F109: Real Time
D110: Assets | E110: Notifications & SMS | F110: Drill Down or Select
D111: Contact Information | E111: ID Type | F111: Real Time
D112: Contact Information | E112: ID Number | F112: Real Time
D113: Assets | E113: Sim serial | F113: Real Time
D114: Assets | E114: Star number value | F114: Real Time
... D123: Contact Information | E123: Credit Score | F123: Real Time
D124: EBU | E124: Contract start and end date
E125: Product wise revenue split
E126: ZSB to be mandatory for business activations and data to be imported from Dynamics

Sheet Direct Sales Agent
A1: # | B1: Sequencing | C1: Component | D1: TOPIC | E1: Details | F1: Direct Sales Agent | AX1: Real Time | AY1: Drill Down or Select | AZ1: N/A
A2: 1 | C2: Account | D2: Account Information | E2: Primary MSISDN | F2: N/A
A3: 2 | C3: Account | D3: Account Information | E3: AM name | F3: N/A
A4: 3 | C4: Account | D4: Account Information | E4: AM mobile | F4: N/A
A5: 4 | C5: Account | D5: Account Information | E5: AM Email | F5: N/A
A6: 5 | C6: Account | D6: Account Information | E6: Manager Email | F6: N/A
A7: 6 | C7: Account | D7: Account Information | E7: Availability/escalation contact
A8: 7 | C8: Account | D8: Account Information | E8: Segment | F8: Real Time
A9: 8 | C9: Account | D9: Account Information | E9: Service Type Number of Connections (Total Per Account + Total Per Plan Type) | F9: Real Time
A10: 9 | C10: Account | D10: Account Information | E10: Account Hierarchy | F10: N/A
A11: 10 | C11: Account | D11: Account Information | E11: Billing Email ID (It should show all the email Ids which are marked for Billing Receipent) | F11: N/A
A12: 11 | C12: Account | D12: Billing & Payments | E12: Postpaid - Monthly Recurring Charge | F12: N/A
A13: 12 | C13: Account | D13: Billing & Payments | E13: Postpaid - Average Bill/Spend | F13: N/A
A14: 13 | C14: Account | D14: Billing & Payments | E14: Prepaid - Monthly Recharge Amount | F14: N/A
A15: 14 | C15: Account | D15: Billing & Payments | E15: Prepaid - Top Recharge Type | F15: N/A
A16: 15 | C16: Account | D16: Account Information | E16: Recent Milestones or Interactions (including all recent purschages add-on, Plan change, activation, change done to MSISDN, account, ticket or activity) | F16: N/A
A17: 16 | C17: Account | D17: Billing & Payments | E17: Latest Bill | F17: N/A
A18: 17 | C18: Account | D18: Billing & Payments | E18: Outstanding Balance | F18: Real Time
