Workbook

Sheet Raw
A1: # | B1: Journey Category | C1: Journey Type | D1: Description | E1: Comment | F1: Desktop | G1: Tablet
A2: 1 | B2: Lead | C2: Create Lead | D2: Creating a lead for new sales as Postpaid, MNP, Fixed Line or for existing customers to Migrate from Pre to Post, Plan upgrade,etc | E2: Guided Journey in Open UI Tablet/Action Through Vanilla (Open UI Desktop) | F2: Yes | G2: Yes
A3: =A2+1 -> 2 | B3: Lead | C3: Manage Lead | D3: Handle the Lead for Completing the Sale, Updating Lead Status, Assigning it to Other User/Queue, View All Leads in Queue, Teams, | E3: Guided Journey in Open UI Tablet/Action Through Vanilla (Open UI Desktop) | F3: Yes | G3: Yes
A4: =A3+1 -> 3 | B4: Lead | C4: Create Upgrade TT | D4: Creating a ticket for Plan Upgrade for Tracking the Plan upgrades | E4: Guided Journey in Open UI Tablet/Action Through Vanilla (Open UI Desktop) | F4: Yes | G4: Yes
A5: =A4+1 -> 4 | B5: Sales | C5: Device Installment | D5: Activating Device Installment against MSISDN for DOI sales | E5: - | F5: Yes | G5: No
A6: =A5+1 -> 5 | B6: Sales | C6: New Fixed line | D6: To Activate New Fixed Line Connection | E6: Guided Journey | F6: Yes | G6: Yes
A7: =A6+1 -> 6 | B7: Sales | C7: New FWA | D7: To Activate New 5G Connection | E7: Guided Journey | F7: Yes | G7: Yes
A8: =A7+1 -> 7 | B8: Sales | C8: New Postpaid | D8: To Activate New Postpaid Number | E8: Guided Journey | F8: Yes | G8: Yes
A9: =A8+1 -> 8 | B9: Sales | C9: Prepaid to Postpaid | D9: To Migrate Existing Prepaid Connectionto Postpaid | E9: Guided Journey | F9: Yes | G9: Yes
A10: =A9+1 -> 9 | B10: Sales | C10: New Prepaid | D10: To Activate New Prepaid Connection | E10: Guided Journey | F10: Yes | G10: Yes
A11: =A10+1 -> 10 | B11: Sales | C11: MNP Prepaid | D11: To Port-In New Prepaid Connection | E11: Guided Journey | F11: Yes | G11: Yes
A12: =A11+1 -> 11 | B12: Sales | C12: MNP Postpaid | D12: To Port-In New Postpaid Connection | E12: Guided Journey | F12: Yes | G12: Yes
A13: =A12+1 -> 12 | B13: Sales | C13: New IOT Tablet | D13: To Activate New IOT Connection | E13: Guided Journey | F13: Yes | G13: Yes
A14: =A13+1 -> 13 | B14: Sales | C14: RFS/Fiber Home Move | D14: To Perform Home for Fixed Line Connection from One RFS Location to Another | E14: Guided Journey | F14: Yes | G14: No
... A162: =A161+1 -> 161 | B162: Disconnect | C162: PTX disconnect | D162: Same as normal disconnect- however it need to checked from EBU fulifilment that PTX is disconnect as well from the backend portal | E162: Action through Vanilla (Open UI desktop) | F162: Yes | G162: No
A163: =A162+1 -> 162 | B163: Manage | C163: Automatic SMS Templates | D163: Upload Automatic SMS for Tickets which triggers on Ticket Submission based on defined LOVs Logic | E163: Action through Vanilla (Open UI desktop) | F163: Yes | G163: No | H163: Newly Added on 09th Feb
A164: =A163+1 -> 163 | B164: Manage | C164: Manual SMS Templates | D164: Upload Manual SMS which is used by teams to Send SMS to Customers for tickets or Calls. | E164: Action through Vanilla (Open UI desktop) | F164: Yes | G164: No | H164: Newly Added on 09th Feb
A165: =A164+1 -> 164 | B165: Manage | C165: Hashtags | D165: Upload Hashtags for Tickets & Call for Tracking the Count of Specific Call Category or Resolution Category | E165: Action through Vanilla (Open UI desktop) | F165: Yes | G165: No | H165: Newly Added on 09th Feb
A166: =A165+1 -> 165 | B166: Manage | C166: Actual Issue | D166: Upload Actual for Tickets, to track the actual issue related to complaints for RCA | E166: Action through Vanilla (Open UI desktop) | F166: Yes | G166: No | H166: Newly Added on 09th Feb

Sheet Open UI Features
A1: # | B1: Journey Category | C1: Journey Type | D1: Description | E1: Comment | F1: Guided journey Desktop | G1: Guided journey Tablet | H1: Desktop vanilla | I1: CBU | J1: EBU | K1: Comments
A2: 1 | B2: Lead | C2: Create Lead | D2: Creating a lead for new sales as Postpaid, MNP, Fixed Line or for existing customers to Migrate from Pre to Post, Plan upgrade,etc | E2: Guided Journey in Open UI Tablet/Action Through Vanilla (Open UI Desktop) | F2: No | G2: Yes | H2: Yes | I2: Yes | J2: No
A3: =A2+1 -> 2 | B3: Lead | C3: Manage Lead | D3: Handle the Lead for Completing the Sale, Updating Lead Status, Assigning it to Other User/Queue, View All Leads in Queue, Teams, | E3: Guided Journey in Open UI Tablet/Action Through Vanilla (Open UI Desktop) | F3: No | G3: Yes | H3: Yes | I3: Yes | J3: No
A4: =A3+1 -> 3 | B4: Lead | C4: Create Upgrade TT | D4: Creating a ticket for Plan Upgrade for Tracking the Plan upgrades | E4: Guided Journey in Open UI Tablet/Action Through Vanilla (Open UI Desktop) | F4: No | G4: Yes | H4: Yes | I4: Yes | J4: No
A5: =A4+1 -> 4 | B5: Sales | C5: Device Installment | D5: Activating Device Installment against MSISDN for DOI sales | E5: - | F5: No | G5: No | H5: Yes | I5: Yes | J5: Yes
A6: =A5+1 -> 5 | B6: Sales | C6: New Fixed line | D6: To Activate New Fixed Line Connection | E6: Guided Journey | F6: Yes | G6: Yes | H6: Yes | I6: Yes | J6: No
A7: =A6+1 -> 6 | B7: Sales | C7: New FWA | D7: To Activate New 5G Connection | E7: Guided Journey | F7: Yes | G7: Yes | H7: Yes | I7: Yes | J7: No
A8: =A7+1 -> 7 | B8: Sales | C8: New Postpaid | D8: To Activate New Postpaid Number | E8: Guided Journey | F8: Yes | G8: Yes | H8: Yes | I8: Yes | J8: No
A9: =A8+1 -> 8 | B9: Sales | C9: Prepaid to Postpaid | D9: To Migrate Existing Prepaid Connectionto Postpaid | E9: Guided Journey | F9: Yes | G9: Yes | H9: Yes | I9: Yes | J9: No
A10: =A9+1 -> 9 | B10: Sales | C10: New Prepaid | D10: To Activate New Prepaid Connection | E10: Guided Journey | F10: No | G10: Yes | H10: Yes | I10: Yes | J10: No
A11: =A10+1 -> 10 | B11: Sales | C11: MNP Prepaid | D11: To Port-In New Prepaid Connection | E11: Guided Journey | F11: No | G11: Yes | H11: Yes | I11: Yes | J11: No
A12: =A11+1 -> 11 | B12: Sales | C12: MNP Postpaid | D12: To Port-In New Postpaid Connection | E12: Guided Journey | F12: Yes | G12: Yes | H12: Yes | I12: Yes | J12: No
A13: =A12+1 -> 12 | B13: Sales | C13: New IOT Tablet | D13: To Activate New IOT Connection | E13: Guided Journey | F13: No | G13: Yes | H13: Yes | I13: No | J13: Yes
A14: =A13+1 -> 13 | B14: Sales | C14: RFS/Fiber Home Move | D14: To Perform Home for Fixed Line Connection from One RFS Location to Another | E14: Guided Journey | F14: Yes | G14: No | H14: Yes | I14: Yes | J14: No
... A31: =A30+1 -> 30 | B31: Support | C31: Adjustment Approval | D31: Aproving Adjustment based on Approval Matrix and Queue | E31: Action through Vanilla (Open UI desktop) | F31: No | G31: No | H31: Yes | I31: Yes | J31: Yes
A32: =A31+1 -> 31 | B32: Support | C32: Updating Contacts | D32: To Update the Contact Details Insight Account, Changing Notification MSISDN, Linking New Contact, MOI Validation, QID Update, Etc | E32: Action through Vanilla (Open UI desktop) | F32: No | G32: No | H32: Yes | I32: Yes | J32: Yes | K32: Retail cannot change primary contact
A33: =A32+1 -> 32 | B33: Support | C33: Documeting Activity | D33: Making activity inside customer account against MSISDN/Ticket/Leads | E33: Action through Vanilla (Open UI desktop) | F33: No | G33: No | H33: Yes | I33: Yes | J33: Yes
A34: =A33+1 -> 33 | B34: Support | C34: Updating Account | D34: To Update the Account Details Insight Account | E34: Action through Vanilla (Open UI desktop) | F34: No | G34: No | H34: Yes | I34: Yes | J34: Yes
A35: =A34+1 -> 34 | B35: Support | C35: Linking Accounts | D35: Linking an Account Against Parent Account or Correcting the Linking | E35: Action through Vanilla (Open UI desktop) | F35: No | G35: No | H35: Yes | I35: No | J35: Yes
A36: =A35+1 -> 35 | B36: Support | C36: Adding Add-on | D36: Adding Add-ons against MSISDN through Modify Order | E36: Action through Vanilla (Open UI desktop) | F36: No | G36: No | H36: Yes | I36: Yes | J36: Yes
A37: =A36+1 -> 36 | B37: Support | C37: Adding Multi-SIM/I-Watch | D37: Adding Multi-SIM/I-Watch against MSISDN through Modify Order and Customization | E37: Action through Vanilla (Open UI desktop) | F37: No | G37: No | H37: Yes | I37: Yes | J37: Yes
A38: =A37+1 -> 37 | B38: Support | C38: Updating Special Management | D38: Selecting the Correct Special management Against Account from Drop Down/ Auto-Stamping from Open UI Tablet Guided Journey for B2B2C | E38: Action through Vanilla (Open UI desktop)/Guided Journey from Open UI Tablet | F38: No | G38: Yes | H38: Yes | I38: Yes | J38: Yes
A39: =A38+1 -> 38 | B39: Support | C39: Deleting Add-on | D39: Deleting Add-ons from MSISDN through Modify Order | E39: Action through Vanilla (Open UI desktop) | F39: No | G39: No | H39: Yes | I39: Yes | J39: Yes
A40: =A39+1 -> 39 | B40: Support | C40: Deleting Multi-SIM/I-Watch | D40: Deleting Multi-SIM/I-Watch from MSISDN through Modify Order and Customization | E40: Action through Vanilla (Open UI desktop) | F40: No | G40: No | H40: Yes | I40: Yes | J40: Yes
A41: =A40+1 -> 40 | B41: Support | C41: Send SMS | D41: Sending an SMS to the customer to MSISDN from Account Page or TT Page | E41: Action through Vanilla (Open UI desktop) | F41: No | G41: No | H41: Yes | I41: Yes | J41: Yes
A42: =A41+1 -> 41 | B42: Support | C42: Create Ticket | D42: Creating a Ticket inside Customer Account for Specific MSISDN | E42: Action through Vanilla (Open UI desktop) | F42: No | G42: No | H42: Yes | I42: Yes | J42: Yes
A43: =A42+1 -> 42 | B43: Support | C43: Send Bill (PDF & XLSX) | D43: Sending Specific Bills on email from Billing Profile | E43: Action through Vanilla (Open UI desktop) | F43: No | G43: No | H43: Yes | I43: Yes | J43: Yes
A44: =A43+1 -> 43 | B44: Support | C44: Prorata Calculator | D44: Calculating the Pro Rata Amount for MSISDN based on BC, Activation Date, Plan Change, Applied Discount and Send SMS with Auto Calculated amount | E44: Action through Vanilla (Open UI desktop) | F44: Yes | G44: yes | H44: yes | I44: Yes | J44: No | K44: Bill calculator SMS is not a journey but a capability
A45: =A44+1 -> 44 | B45: Support | C45: View & Export Bill (PDF & XLSX) | D45: View the details of Bill Charges and Export Bills | E45: Action through Vanilla (Open UI desktop) | F45: No | G45: No | H45: Yes | I45: Yes | J45: Yes
A46: =A45+1 -> 45 | B46: Support | C46: View and Manage orders | D46: It's a View | E46: View in Vanilla (Open UI desktop) | F46: Yes | G46: yes | H46: yes | I46: Yes | J46: Yes | K46: Not a guided journey but a view
A47: =A46+1 -> 46 | B47: Support | C47: View public notes | D47: It's a View | E47: View in Vanilla (Open UI desktop) | F47: Yes | G47: no | H47: yes | I47: Yes | J47: Yes | K47: Not a guided journey but a view
A48: =A47+1 -> 47 | B48: Support | C48: View Attachments | D48: It's a View | E48: View in Vanilla (Open UI desktop) | F48: Yes | G48: no | H48: yes | I48: Yes | J48: Yes | K48: Not a guided journey but a view
A49: =A48+1 -> 48 | B49: Support | C49: View Surepay balance | D49: It's a View | E49: View in Vanilla (Open UI desktop) | F49: No | G49: No | H49: Yes | I49: Yes | J49: Yes
A50: =A49+1 -> 49 | B50: Support | C50: View Detailed Usage | D50: It's a View | E50: View in Vanilla (Open UI desktop) | F50: No | G50: No | H50: Yes | I50: Yes | J50: Yes
A51: =A50+1 -> 50 | B51: Support | C51: Escalate Ticket | D51: Escalate a Ticket by Assigning it to you and Update Escalate Reason which auto-triggers an email to TT Queue Owner | E51: Action through Vanilla (Open UI desktop) | F51: No | G51: No | H51: Yes | I51: Yes | J51: Yes | K51: We want this for Tablet
A52: =A51+1 -> 51 | B52: Support | C52: Get PIN/PUK | D52: Getting PIN/PUK for MSISDN through one Click on Get PIN/PUK tab | E52: Action through Vanilla (Open UI desktop) | F52: No | G52: No | H52: Yes | I52: Yes | J52: Yes
A53: =A52+1 -> 52 | B53: Support | C53: End Data Session | D53: Ending the Ongoing Data Session for Specific MSISDNs with one click on End Data Session which auto creates a ticket for End Data Session and triggering an request in backend to refresh the Data Session | E53: Action through Vanilla (Open UI desktop) | F53: No | G53: No | H53: Yes | I53: Yes | J53: Yes
A54: =A53+1 -> 53 | B54: Support | C54: Add Discount | D54: Adding Discount against MSISDN through Modify Order | E54: Action through Vanilla (Open UI desktop) | F54: No | G54: No | H54: Yes | I54: Yes | J54: Yes
A55: =A54+1 -> 54 | B55: Support | C55: Primary number | D55: Adding/Changing/Updating Primary Number for through Modify Order | E55: Action through Vanilla (Open UI desktop) | F55: No | G55: No | H55: Yes | I55: Yes | J55: Yes
A56: =A55+1 -> 55 | B56: Support | C56: Check user ID/AM Code | D56: It's a View | E56: View in Vanilla (Open UI desktop) | F56: No | G56: No | H56: Yes | I56: No | J56: Yes
...

Sheet Summary Combination List
B1: Type of Activation | C1: Combination 1 | D1: Combination 2 | E1: Combination 3 | F1: T&Cs Summary
B2: Postpaid | C2: HRN Customer | D2: N/A | E2: N/A
B3: Postpaid | C3: HRN Customer | D3: Star Number | E3: N/A
B4: Postpaid | C4: HRN Customer | D4: Star Number | E4: Device Instalment
B5: Postpaid | C5: Non HRN Customer | D5: N/A | E5: N/A
B6: Postpaid | C6: Non HRN Customer | D6: Star Number | E6: N/A
B7: Postpaid | C7: Non HRN Customer | D7: Star Number | E7: Device Instalment
B8: Prepaid | C8: QID | D8: N/A | E8: N/A
B9: Prepaid | C9: Passport | D9: N/A | E9: N/A
B10: Fixed Line | C10: New Customer (Never Availed Fixed Before) | D10: N/A | E10: N/A
B11: Fixed Line | C11: Existing Customer (Availed Fixed Before) | D11: N/A | E11: N/A
B12: FWA | C12: N/A | D12: N/A | E12: N/A
B13: Pre to Post | C13: HRN Customer | D13: N/A | E13: N/A
... B18: Device Instalment | C18: Non HRN Customer | D18: N/A | E18: N/A

Sheet Sheet1
A2: SNO | B2: iTem | E2: 1 dedicated Vodafone SPOC - Subject Matter Expert to approve flow & clarify doubts daily
A3: 1 | B3: Journeys | C3: 165 | D3: 16 | G3: 165 | H3: =G3*G4*G5*G6 -> 7425
A4: 2 | B4: Aprox screens - Positive | C4: 5 | D4: 5 | E4: Op : 1 Resources required - 2 + 1 buffer = 3 | G4: 5 | H4: =G3*(SUM(G4:G6)) -> 1815
A5: 3 | B5: Aprox screens - Negetive | C5: 3 | D5: 3 | E5: Resources working Conditions (excluding ramadan & eid break) | G5: 3
A6: 4 | B6: Popups | C6: 3 | D6: 3 | E6: Resources to work 5 days a week (including eid) | G6: 3
B7: Expected screens Desktop | C7: =C3*(C4+C5+C6) -> 1815 | D7: =D3*(D4+D5+D6) -> 176 | E7: Resources to work 8 hours a day (including Ramadan)
E8: No eid break
A9: 1 | B9: Expected screens Desktop | C9: 1815 | E9: No planned leaves during project
A10: 2 | B10: Expected screens Tablet | C10: 176
B11: Total screens | C11: =C9+C10 -> 1991 | E11: Opt : 2 Resources required - 3 + 1 buffer = 4
B12: Timelines (Normal) | E12: Resources working Conditions (including ramadan hrs & Eid break)
B13: Mar 1-31 | C13: 23 | E13: Resources to work 5 days a week (excluding 1 week eid break)
B14: Apr 1-30 | C14: 22 | E14: Resources to work 5 hours a day (during Ramadan)
B15: Prepare DSM | C15: 2 | E15: 5 days eid break
B16: Days-1Mar-1May | C16: =C13+C14-C15 -> 43 | E16: No planned leaves during project
B17: Screens per day to meet target | C17: =C11/C16 -> 46.302326
B18: Screens per hour to meet target | C18: =C17/7 -> 6.6146179
B20: Actual screens per hour | C20: 4
B21: Resources required | C21: =C18/4 -> 1.6536545
B23: Timelines (Ramadan & Eid)
B24: Mar 1-31 | C24: 18
B25: Apr 1-30 | C25: 22
B26: Prepare DSM | C26: 2
B27: Days-1Mar-1May (with eid holidays) | C27: =C24+C25 -> 40
B28: Screens per day to meet target | C28: =C11/C27 -> 49.775
B29: Screens per hour to meet target | C29: =C28/7 -> 7.1107143
B31: Actual screens per hour | C31: =C29/4 -> 1.7776786
B32: Resources required | C32: =C29/C31 -> 4

Sheet Summary
A1: Journey Types Summary
A3: Journey Category | B3: Count | C3: % of Total
A4: Lead | B4: =COUNTIF(Raw!B:B,"Lead") -> 3 | C4: =B4/B9 -> 0.018181818
A5: Sales | B5: =COUNTIF(Raw!B:B,"Sales") -> 18 | C5: =B5/B9 -> 0.10909091
A6: Support | B6: =COUNTIF(Raw!B:B,"Support") -> 79 | C6: =B6/B9 -> 0.47878788
A7: Manage | B7: =COUNTIF(Raw!B:B,"Manage") -> 62 | C7: =B7/B9 -> 0.37575758
A8: Disconnect | B8: =COUNTIF(Raw!B:B,"Disconnect") -> 3 | C8: =B8/B9 -> 0.018181818
A9: Total | B9: =SUM(B4:B8) -> 165 | C9: =SUM(C4:C8) -> 1
A11: Platform Support | B11: Count | C11: % of Total
A12: Desktop Supported (Yes) | B12: =COUNTIF(Raw!F:F,"Yes") -> 165 | C12: =B12/$B$9 -> 1
A13: Tablet Supported (Yes) | B13: =COUNTIF(Raw!G:G,"Yes") -> 16 | C13: =B13/$B$9 -> 0.096969697
A14: Both Desktop & Tablet | B14: =COUNTIFS(Raw!F:F,"Yes",Raw!G:G,"Yes") -> 16 | C14: =B14/$B$9 -> 0.096969697
A15: Desktop Only | B15: =COUNTIFS(Raw!F:F,"Yes",Raw!G:G,"No") -> 149 | C15: =B15/$B$9 -> 0.9030303
A17: Action Type | B17: Count | C17: % of Total
A18: Guided Journey | B18: =COUNTIF(Raw!E:E,"*Guided Journey*") -> 17 | C18: =B18/$B$9 -> 0.1030303
A19: Action through Vanilla | B19: =COUNTIF(Raw!E:E,"*Action*Vanilla*") -> 115 | C19: =B19/$B$9 -> 0.6969697
A20: View Only | B20: =COUNTIF(Raw!E:E,"*View*") -> 35 | C20: =B20/$B$9 -> 0.21212121

Sheet Summary_Sheet1
A1: Sheet1 Summary - Project Timeline & Resource Planning
A3: Category | B3: Metric | C3: Value
A4: Screen Counts | B4: Total Journeys | C4: =Sheet1!C3 -> 165
B5: Approx Screens - Positive | C5: =Sheet1!C4 -> 5
B6: Approx Screens - Negative | C6: =Sheet1!C5 -> 3
B7: Popups | C7: =Sheet1!C6 -> 3
B8: Expected Screens Desktop | C8: =Sheet1!C9 -> 1815
B9: Expected Screens Tablet | C9: =Sheet1!C10 -> 176
B10: Total Screens | C10: =Sheet1!C11 -> 1991
A12: Normal Timeline | B12: March Days | C12: =Sheet1!C13 -> 23
B13: April Days | C13: =Sheet1!C14 -> 22
B14: Prepare DSM Days | C14: =Sheet1!C15 -> 2
B15: Total Working Days (Mar-May) | C15: =Sheet1!C16 -> 43
B16: Screens per Day Target | C16: =Sheet1!C17 -> 46.302326
B17: Screens per Hour Target | C17: =Sheet1!C18 -> 6.6146179
B18: Actual Screens per Hour | C18: =Sheet1!C20 -> 4
B19: Resources Required | C19: =Sheet1!C21 -> 1.6536545
A21: Ramadan & Eid Timeline | B21: March Days | C21: =Sheet1!C24 -> 18
B22: April Days | C22: =Sheet1!C25 -> 22
B23: Prepare DSM Days | C23: =Sheet1!C26 -> 2
B24: Total Working Days (with Eid) | C24: =Sheet1!C27 -> 40
B25: Screens per Day Target | C25: =Sheet1!C28 -> 49.775
B26: Screens per Hour Target | C26: =Sheet1!C29 -> 7.1107143
B27: Actual Screens per Hour | C27: =Sheet1!C31 -> 1.7776786
B28: Resources Required | C28: =Sheet1!C32 -> 4
A30: Resource Options | B30: Option 1 (Normal) | C30: 2 + 1 buffer = 3 resources
B31: Option 2 (Ramadan/Eid) | C31: 3 + 1 buffer = 4 resources
